<?xml version="1.0" encoding="UTF-8"?>
<testng-results ignored="0" total="34" passed="12" failed="16" skipped="6">
  <reporter-output>
  </reporter-output>
  <suite started-at="2022-09-10T00:49:31 IST" name="EmployeesRestAPISuite" finished-at="2022-09-10T00:49:56 IST" duration-ms="25173">
    <groups>
    </groups>
    <test started-at="2022-09-10T00:49:31 IST" name="EmployeesRestAPITest" finished-at="2022-09-10T00:49:56 IST" duration-ms="25173">
      <class name="com.employeeapi.testCases.TC003_Post_Employee_Record">
        <test-method is-config="true" signature="setup()[pri:0, instance:com.employeeapi.testCases.TC003_Post_Employee_Record@478190fc]" started-at="2022-09-10T00:49:42 IST" name="setup" finished-at="2022-09-10T00:49:42 IST" duration-ms="6" status="PASS">
          <reporter-output>
          </reporter-output>
        </test-method> <!-- setup -->
        <test-method is-config="true" signature="createEmployee()[pri:0, instance:com.employeeapi.testCases.TC003_Post_Employee_Record@478190fc]" started-at="2022-09-10T00:49:42 IST" name="createEmployee" finished-at="2022-09-10T00:49:48 IST" duration-ms="5844" status="PASS">
          <reporter-output>
          </reporter-output>
        </test-method> <!-- createEmployee -->
        <test-method signature="checkContentType()[pri:0, instance:com.employeeapi.testCases.TC003_Post_Employee_Record@478190fc]" started-at="2022-09-10T00:49:48 IST" name="checkContentType" finished-at="2022-09-10T00:49:48 IST" duration-ms="3" status="PASS">
          <reporter-output>
          </reporter-output>
        </test-method> <!-- checkContentType -->
        <test-method signature="checkResposeBody()[pri:0, instance:com.employeeapi.testCases.TC003_Post_Employee_Record@478190fc]" started-at="2022-09-10T00:49:48 IST" name="checkResposeBody" finished-at="2022-09-10T00:49:48 IST" duration-ms="7" status="FAIL">
          <exception class="java.lang.AssertionError">
            <message>
              <![CDATA[expected [true] but found [false]]]>
            </message>
            <full-stacktrace>
              <![CDATA[java.lang.AssertionError: expected [true] but found [false]
at org.testng.Assert.fail(Assert.java:110)
at org.testng.Assert.failNotEquals(Assert.java:1413)
at org.testng.Assert.assertEqualsImpl(Assert.java:149)
at org.testng.Assert.assertEquals(Assert.java:131)
at org.testng.Assert.assertEquals(Assert.java:976)
at org.testng.Assert.assertEquals(Assert.java:1010)
at com.employeeapi.testCases.TC003_Post_Employee_Record.checkResposeBody(TC003_Post_Employee_Record.java:68)
at java.base/jdk.internal.reflect.NativeMethodAccessorImpl.invoke0(Native Method)
at java.base/jdk.internal.reflect.NativeMethodAccessorImpl.invoke(NativeMethodAccessorImpl.java:77)
at java.base/jdk.internal.reflect.DelegatingMethodAccessorImpl.invoke(DelegatingMethodAccessorImpl.java:43)
at java.base/java.lang.reflect.Method.invoke(Method.java:568)
at org.testng.internal.invokers.MethodInvocationHelper.invokeMethod(MethodInvocationHelper.java:139)
at org.testng.internal.invokers.TestInvoker.invokeMethod(TestInvoker.java:677)
at org.testng.internal.invokers.TestInvoker.invokeTestMethod(TestInvoker.java:221)
at org.testng.internal.invokers.MethodRunner.runInSequence(MethodRunner.java:50)
at org.testng.internal.invokers.TestInvoker$MethodInvocationAgent.invoke(TestInvoker.java:962)
at org.testng.internal.invokers.TestInvoker.invokeTestMethods(TestInvoker.java:194)
at org.testng.internal.invokers.TestMethodWorker.invokeTestMethods(TestMethodWorker.java:148)
at org.testng.internal.invokers.TestMethodWorker.run(TestMethodWorker.java:128)
at java.base/java.util.ArrayList.forEach(ArrayList.java:1511)
at org.testng.TestRunner.privateRun(TestRunner.java:806)
at org.testng.TestRunner.run(TestRunner.java:601)
at org.testng.SuiteRunner.runTest(SuiteRunner.java:433)
at org.testng.SuiteRunner.runSequentially(SuiteRunner.java:427)
at org.testng.SuiteRunner.privateRun(SuiteRunner.java:387)
at org.testng.SuiteRunner.run(SuiteRunner.java:330)
at org.testng.SuiteRunnerWorker.runSuite(SuiteRunnerWorker.java:52)
at org.testng.SuiteRunnerWorker.run(SuiteRunnerWorker.java:95)
at org.testng.TestNG.runSuitesSequentially(TestNG.java:1256)
at org.testng.TestNG.runSuitesLocally(TestNG.java:1176)
at org.testng.TestNG.runSuites(TestNG.java:1099)
at org.testng.TestNG.run(TestNG.java:1067)
at org.testng.remote.AbstractRemoteTestNG.run(AbstractRemoteTestNG.java:115)
at org.testng.remote.RemoteTestNG.initAndRun(RemoteTestNG.java:251)
at org.testng.remote.RemoteTestNG.main(RemoteTestNG.java:77)
]]>
            </full-stacktrace>
          </exception> <!-- java.lang.AssertionError -->
          <reporter-output>
          </reporter-output>
        </test-method> <!-- checkResposeBody -->
        <test-method signature="checkStatusCode()[pri:0, instance:com.employeeapi.testCases.TC003_Post_Employee_Record@478190fc]" started-at="2022-09-10T00:49:48 IST" name="checkStatusCode" finished-at="2022-09-10T00:49:48 IST" duration-ms="15" status="FAIL">
          <exception class="java.lang.AssertionError">
            <message>
              <![CDATA[expected [200] but found [429]]]>
            </message>
            <full-stacktrace>
              <![CDATA[java.lang.AssertionError: expected [200] but found [429]
at org.testng.Assert.fail(Assert.java:110)
at org.testng.Assert.failNotEquals(Assert.java:1413)
at org.testng.Assert.assertEqualsImpl(Assert.java:149)
at org.testng.Assert.assertEquals(Assert.java:131)
at org.testng.Assert.assertEquals(Assert.java:1240)
at org.testng.Assert.assertEquals(Assert.java:1274)
at com.employeeapi.testCases.TC003_Post_Employee_Record.checkStatusCode(TC003_Post_Employee_Record.java:76)
at java.base/jdk.internal.reflect.NativeMethodAccessorImpl.invoke0(Native Method)
at java.base/jdk.internal.reflect.NativeMethodAccessorImpl.invoke(NativeMethodAccessorImpl.java:77)
at java.base/jdk.internal.reflect.DelegatingMethodAccessorImpl.invoke(DelegatingMethodAccessorImpl.java:43)
at java.base/java.lang.reflect.Method.invoke(Method.java:568)
at org.testng.internal.invokers.MethodInvocationHelper.invokeMethod(MethodInvocationHelper.java:139)
at org.testng.internal.invokers.TestInvoker.invokeMethod(TestInvoker.java:677)
at org.testng.internal.invokers.TestInvoker.invokeTestMethod(TestInvoker.java:221)
at org.testng.internal.invokers.MethodRunner.runInSequence(MethodRunner.java:50)
at org.testng.internal.invokers.TestInvoker$MethodInvocationAgent.invoke(TestInvoker.java:962)
at org.testng.internal.invokers.TestInvoker.invokeTestMethods(TestInvoker.java:194)
at org.testng.internal.invokers.TestMethodWorker.invokeTestMethods(TestMethodWorker.java:148)
at org.testng.internal.invokers.TestMethodWorker.run(TestMethodWorker.java:128)
at java.base/java.util.ArrayList.forEach(ArrayList.java:1511)
at org.testng.TestRunner.privateRun(TestRunner.java:806)
at org.testng.TestRunner.run(TestRunner.java:601)
at org.testng.SuiteRunner.runTest(SuiteRunner.java:433)
at org.testng.SuiteRunner.runSequentially(SuiteRunner.java:427)
at org.testng.SuiteRunner.privateRun(SuiteRunner.java:387)
at org.testng.SuiteRunner.run(SuiteRunner.java:330)
at org.testng.SuiteRunnerWorker.runSuite(SuiteRunnerWorker.java:52)
at org.testng.SuiteRunnerWorker.run(SuiteRunnerWorker.java:95)
at org.testng.TestNG.runSuitesSequentially(TestNG.java:1256)
at org.testng.TestNG.runSuitesLocally(TestNG.java:1176)
at org.testng.TestNG.runSuites(TestNG.java:1099)
at org.testng.TestNG.run(TestNG.java:1067)
at org.testng.remote.AbstractRemoteTestNG.run(AbstractRemoteTestNG.java:115)
at org.testng.remote.RemoteTestNG.initAndRun(RemoteTestNG.java:251)
at org.testng.remote.RemoteTestNG.main(RemoteTestNG.java:77)
]]>
            </full-stacktrace>
          </exception> <!-- java.lang.AssertionError -->
          <reporter-output>
          </reporter-output>
        </test-method> <!-- checkStatusCode -->
        <test-method signature="checkcontentEncoding()[pri:0, instance:com.employeeapi.testCases.TC003_Post_Employee_Record@478190fc]" started-at="2022-09-10T00:49:48 IST" name="checkcontentEncoding" finished-at="2022-09-10T00:49:48 IST" duration-ms="2" status="PASS">
          <reporter-output>
          </reporter-output>
        </test-method> <!-- checkcontentEncoding -->
        <test-method signature="checkserverType()[pri:0, instance:com.employeeapi.testCases.TC003_Post_Employee_Record@478190fc]" started-at="2022-09-10T00:49:48 IST" name="checkserverType" finished-at="2022-09-10T00:49:48 IST" duration-ms="1" status="FAIL">
          <exception class="java.lang.AssertionError">
            <message>
              <![CDATA[expected [nginx/1.14.1] but found [Apache]]]>
            </message>
            <full-stacktrace>
              <![CDATA[java.lang.AssertionError: expected [nginx/1.14.1] but found [Apache]
at org.testng.Assert.fail(Assert.java:110)
at org.testng.Assert.failNotEquals(Assert.java:1413)
at org.testng.Assert.assertEqualsImpl(Assert.java:149)
at org.testng.Assert.assertEquals(Assert.java:131)
at org.testng.Assert.assertEquals(Assert.java:655)
at org.testng.Assert.assertEquals(Assert.java:665)
at com.employeeapi.testCases.TC003_Post_Employee_Record.checkserverType(TC003_Post_Employee_Record.java:95)
at java.base/jdk.internal.reflect.NativeMethodAccessorImpl.invoke0(Native Method)
at java.base/jdk.internal.reflect.NativeMethodAccessorImpl.invoke(NativeMethodAccessorImpl.java:77)
at java.base/jdk.internal.reflect.DelegatingMethodAccessorImpl.invoke(DelegatingMethodAccessorImpl.java:43)
at java.base/java.lang.reflect.Method.invoke(Method.java:568)
at org.testng.internal.invokers.MethodInvocationHelper.invokeMethod(MethodInvocationHelper.java:139)
at org.testng.internal.invokers.TestInvoker.invokeMethod(TestInvoker.java:677)
at org.testng.internal.invokers.TestInvoker.invokeTestMethod(TestInvoker.java:221)
at org.testng.internal.invokers.MethodRunner.runInSequence(MethodRunner.java:50)
at org.testng.internal.invokers.TestInvoker$MethodInvocationAgent.invoke(TestInvoker.java:962)
at org.testng.internal.invokers.TestInvoker.invokeTestMethods(TestInvoker.java:194)
at org.testng.internal.invokers.TestMethodWorker.invokeTestMethods(TestMethodWorker.java:148)
at org.testng.internal.invokers.TestMethodWorker.run(TestMethodWorker.java:128)
at java.base/java.util.ArrayList.forEach(ArrayList.java:1511)
at org.testng.TestRunner.privateRun(TestRunner.java:806)
at org.testng.TestRunner.run(TestRunner.java:601)
at org.testng.SuiteRunner.runTest(SuiteRunner.java:433)
at org.testng.SuiteRunner.runSequentially(SuiteRunner.java:427)
at org.testng.SuiteRunner.privateRun(SuiteRunner.java:387)
at org.testng.SuiteRunner.run(SuiteRunner.java:330)
at org.testng.SuiteRunnerWorker.runSuite(SuiteRunnerWorker.java:52)
at org.testng.SuiteRunnerWorker.run(SuiteRunnerWorker.java:95)
at org.testng.TestNG.runSuitesSequentially(TestNG.java:1256)
at org.testng.TestNG.runSuitesLocally(TestNG.java:1176)
at org.testng.TestNG.runSuites(TestNG.java:1099)
at org.testng.TestNG.run(TestNG.java:1067)
at org.testng.remote.AbstractRemoteTestNG.run(AbstractRemoteTestNG.java:115)
at org.testng.remote.RemoteTestNG.initAndRun(RemoteTestNG.java:251)
at org.testng.remote.RemoteTestNG.main(RemoteTestNG.java:77)
]]>
            </full-stacktrace>
          </exception> <!-- java.lang.AssertionError -->
          <reporter-output>
          </reporter-output>
        </test-method> <!-- checkserverType -->
        <test-method signature="checkstatusLine()[pri:0, instance:com.employeeapi.testCases.TC003_Post_Employee_Record@478190fc]" started-at="2022-09-10T00:49:48 IST" name="checkstatusLine" finished-at="2022-09-10T00:49:48 IST" duration-ms="6" status="FAIL">
          <exception class="java.lang.AssertionError">
            <message>
              <![CDATA[expected [HTTP/1.1 200 OK] but found [HTTP/1.1 429 Too Many Requests]]]>
            </message>
            <full-stacktrace>
              <![CDATA[java.lang.AssertionError: expected [HTTP/1.1 200 OK] but found [HTTP/1.1 429 Too Many Requests]
at org.testng.Assert.fail(Assert.java:110)
at org.testng.Assert.failNotEquals(Assert.java:1413)
at org.testng.Assert.assertEqualsImpl(Assert.java:149)
at org.testng.Assert.assertEquals(Assert.java:131)
at org.testng.Assert.assertEquals(Assert.java:655)
at org.testng.Assert.assertEquals(Assert.java:665)
at com.employeeapi.testCases.TC003_Post_Employee_Record.checkstatusLine(TC003_Post_Employee_Record.java:82)
at java.base/jdk.internal.reflect.NativeMethodAccessorImpl.invoke0(Native Method)
at java.base/jdk.internal.reflect.NativeMethodAccessorImpl.invoke(NativeMethodAccessorImpl.java:77)
at java.base/jdk.internal.reflect.DelegatingMethodAccessorImpl.invoke(DelegatingMethodAccessorImpl.java:43)
at java.base/java.lang.reflect.Method.invoke(Method.java:568)
at org.testng.internal.invokers.MethodInvocationHelper.invokeMethod(MethodInvocationHelper.java:139)
at org.testng.internal.invokers.TestInvoker.invokeMethod(TestInvoker.java:677)
at org.testng.internal.invokers.TestInvoker.invokeTestMethod(TestInvoker.java:221)
at org.testng.internal.invokers.MethodRunner.runInSequence(MethodRunner.java:50)
at org.testng.internal.invokers.TestInvoker$MethodInvocationAgent.invoke(TestInvoker.java:962)
at org.testng.internal.invokers.TestInvoker.invokeTestMethods(TestInvoker.java:194)
at org.testng.internal.invokers.TestMethodWorker.invokeTestMethods(TestMethodWorker.java:148)
at org.testng.internal.invokers.TestMethodWorker.run(TestMethodWorker.java:128)
at java.base/java.util.ArrayList.forEach(ArrayList.java:1511)
at org.testng.TestRunner.privateRun(TestRunner.java:806)
at org.testng.TestRunner.run(TestRunner.java:601)
at org.testng.SuiteRunner.runTest(SuiteRunner.java:433)
at org.testng.SuiteRunner.runSequentially(SuiteRunner.java:427)
at org.testng.SuiteRunner.privateRun(SuiteRunner.java:387)
at org.testng.SuiteRunner.run(SuiteRunner.java:330)
at org.testng.SuiteRunnerWorker.runSuite(SuiteRunnerWorker.java:52)
at org.testng.SuiteRunnerWorker.run(SuiteRunnerWorker.java:95)
at org.testng.TestNG.runSuitesSequentially(TestNG.java:1256)
at org.testng.TestNG.runSuitesLocally(TestNG.java:1176)
at org.testng.TestNG.runSuites(TestNG.java:1099)
at org.testng.TestNG.run(TestNG.java:1067)
at org.testng.remote.AbstractRemoteTestNG.run(AbstractRemoteTestNG.java:115)
at org.testng.remote.RemoteTestNG.initAndRun(RemoteTestNG.java:251)
at org.testng.remote.RemoteTestNG.main(RemoteTestNG.java:77)
]]>
            </full-stacktrace>
          </exception> <!-- java.lang.AssertionError -->
          <reporter-output>
          </reporter-output>
        </test-method> <!-- checkstatusLine -->
        <test-method is-config="true" signature="tearDown()[pri:0, instance:com.employeeapi.testCases.TC003_Post_Employee_Record@478190fc]" started-at="2022-09-10T00:49:48 IST" name="tearDown" finished-at="2022-09-10T00:49:48 IST" duration-ms="1" status="PASS">
          <reporter-output>
          </reporter-output>
        </test-method> <!-- tearDown -->
      </class> <!-- com.employeeapi.testCases.TC003_Post_Employee_Record -->
      <class name="com.employeeapi.testCases.TC005_Delete_Employee_Record">
        <test-method is-config="true" signature="setup()[pri:0, instance:com.employeeapi.testCases.TC005_Delete_Employee_Record@7e07db1f]" started-at="2022-09-10T00:49:55 IST" name="setup" finished-at="2022-09-10T00:49:55 IST" duration-ms="8" status="PASS">
          <reporter-output>
          </reporter-output>
        </test-method> <!-- setup -->
        <test-method is-config="true" signature="deleteEmployee()[pri:0, instance:com.employeeapi.testCases.TC005_Delete_Employee_Record@7e07db1f]" started-at="2022-09-10T00:49:55 IST" name="deleteEmployee" finished-at="2022-09-10T00:49:56 IST" duration-ms="998" status="FAIL">
          <exception class="io.restassured.path.json.exception.JsonPathException">
            <message>
              <![CDATA[Failed to parse the JSON document]]>
            </message>
            <full-stacktrace>
              <![CDATA[io.restassured.path.json.exception.JsonPathException: Failed to parse the JSON document
at io.restassured.path.json.JsonPath$ExceptionCatcher.invoke(JsonPath.java:1002)
at io.restassured.path.json.JsonPath$4.doParseWith(JsonPath.java:967)
at io.restassured.path.json.JsonPath$JsonParser.parseWith(JsonPath.java:1047)
at io.restassured.path.json.JsonPath.get(JsonPath.java:202)
at com.employeeapi.testCases.TC005_Delete_Employee_Record.deleteEmployee(TC005_Delete_Employee_Record.java:46)
at java.base/jdk.internal.reflect.NativeMethodAccessorImpl.invoke0(Native Method)
at java.base/jdk.internal.reflect.NativeMethodAccessorImpl.invoke(NativeMethodAccessorImpl.java:77)
at java.base/jdk.internal.reflect.DelegatingMethodAccessorImpl.invoke(DelegatingMethodAccessorImpl.java:43)
at java.base/java.lang.reflect.Method.invoke(Method.java:568)
at org.testng.internal.invokers.MethodInvocationHelper.invokeMethod(MethodInvocationHelper.java:139)
at org.testng.internal.invokers.MethodInvocationHelper.invokeMethodConsideringTimeout(MethodInvocationHelper.java:69)
at org.testng.internal.invokers.ConfigInvoker.invokeConfigurationMethod(ConfigInvoker.java:361)
at org.testng.internal.invokers.ConfigInvoker.invokeConfigurations(ConfigInvoker.java:296)
at org.testng.internal.invokers.TestMethodWorker.invokeBeforeClassMethods(TestMethodWorker.java:180)
at org.testng.internal.invokers.TestMethodWorker.run(TestMethodWorker.java:122)
at java.base/java.util.ArrayList.forEach(ArrayList.java:1511)
at org.testng.TestRunner.privateRun(TestRunner.java:806)
at org.testng.TestRunner.run(TestRunner.java:601)
at org.testng.SuiteRunner.runTest(SuiteRunner.java:433)
at org.testng.SuiteRunner.runSequentially(SuiteRunner.java:427)
at org.testng.SuiteRunner.privateRun(SuiteRunner.java:387)
at org.testng.SuiteRunner.run(SuiteRunner.java:330)
at org.testng.SuiteRunnerWorker.runSuite(SuiteRunnerWorker.java:52)
at org.testng.SuiteRunnerWorker.run(SuiteRunnerWorker.java:95)
at org.testng.TestNG.runSuitesSequentially(TestNG.java:1256)
at org.testng.TestNG.runSuitesLocally(TestNG.java:1176)
at org.testng.TestNG.runSuites(TestNG.java:1099)
at org.testng.TestNG.run(TestNG.java:1067)
at org.testng.remote.AbstractRemoteTestNG.run(AbstractRemoteTestNG.java:115)
at org.testng.remote.RemoteTestNG.initAndRun(RemoteTestNG.java:251)
at org.testng.remote.RemoteTestNG.main(RemoteTestNG.java:77)
Caused by: groovy.json.JsonException: Lexing failed on line: 1, column: 1, while reading '<', no possible valid JSON value or punctuation could be recognized.
at groovy.json.JsonLexer.nextToken(JsonLexer.java:86)
at groovy.json.JsonLexer$nextToken.call(Unknown Source)
at org.codehaus.groovy.runtime.callsite.CallSiteArray.defaultCall(CallSiteArray.java:46)
at org.codehaus.groovy.runtime.callsite.AbstractCallSite.call(AbstractCallSite.java:125)
at org.codehaus.groovy.runtime.callsite.AbstractCallSite.call(AbstractCallSite.java:130)
at io.restassured.internal.path.json.ConfigurableJsonSlurper.parse(ConfigurableJsonSlurper.groovy:97)
at io.restassured.internal.path.json.ConfigurableJsonSlurper$parse.callCurrent(Unknown Source)
at org.codehaus.groovy.runtime.callsite.CallSiteArray.defaultCallCurrent(CallSiteArray.java:50)
at org.codehaus.groovy.runtime.callsite.AbstractCallSite.callCurrent(AbstractCallSite.java:171)
at org.codehaus.groovy.runtime.callsite.AbstractCallSite.callCurrent(AbstractCallSite.java:185)
at io.restassured.internal.path.json.ConfigurableJsonSlurper.parseText(ConfigurableJsonSlurper.groovy:83)
at io.restassured.path.json.JsonPath$4$1.method(JsonPath.java:965)
at io.restassured.path.json.JsonPath$ExceptionCatcher.invoke(JsonPath.java:1000)
... 30 more
]]>
            </full-stacktrace>
          </exception> <!-- io.restassured.path.json.exception.JsonPathException -->
          <reporter-output>
          </reporter-output>
        </test-method> <!-- deleteEmployee -->
        <test-method signature="checkContentType()[pri:0, instance:com.employeeapi.testCases.TC005_Delete_Employee_Record@7e07db1f]" started-at="2022-09-10T00:49:56 IST" name="checkContentType" finished-at="2022-09-10T00:49:56 IST" duration-ms="1" status="SKIP">
          <exception class="io.restassured.path.json.exception.JsonPathException">
            <message>
              <![CDATA[Failed to parse the JSON document]]>
            </message>
            <full-stacktrace>
              <![CDATA[io.restassured.path.json.exception.JsonPathException: Failed to parse the JSON document
at io.restassured.path.json.JsonPath$ExceptionCatcher.invoke(JsonPath.java:1002)
at io.restassured.path.json.JsonPath$4.doParseWith(JsonPath.java:967)
at io.restassured.path.json.JsonPath$JsonParser.parseWith(JsonPath.java:1047)
at io.restassured.path.json.JsonPath.get(JsonPath.java:202)
at com.employeeapi.testCases.TC005_Delete_Employee_Record.deleteEmployee(TC005_Delete_Employee_Record.java:46)
at java.base/jdk.internal.reflect.NativeMethodAccessorImpl.invoke0(Native Method)
at java.base/jdk.internal.reflect.NativeMethodAccessorImpl.invoke(NativeMethodAccessorImpl.java:77)
at java.base/jdk.internal.reflect.DelegatingMethodAccessorImpl.invoke(DelegatingMethodAccessorImpl.java:43)
at java.base/java.lang.reflect.Method.invoke(Method.java:568)
at org.testng.internal.invokers.MethodInvocationHelper.invokeMethod(MethodInvocationHelper.java:139)
at org.testng.internal.invokers.MethodInvocationHelper.invokeMethodConsideringTimeout(MethodInvocationHelper.java:69)
at org.testng.internal.invokers.ConfigInvoker.invokeConfigurationMethod(ConfigInvoker.java:361)
at org.testng.internal.invokers.ConfigInvoker.invokeConfigurations(ConfigInvoker.java:296)
at org.testng.internal.invokers.TestMethodWorker.invokeBeforeClassMethods(TestMethodWorker.java:180)
at org.testng.internal.invokers.TestMethodWorker.run(TestMethodWorker.java:122)
at java.base/java.util.ArrayList.forEach(ArrayList.java:1511)
at org.testng.TestRunner.privateRun(TestRunner.java:806)
at org.testng.TestRunner.run(TestRunner.java:601)
at org.testng.SuiteRunner.runTest(SuiteRunner.java:433)
at org.testng.SuiteRunner.runSequentially(SuiteRunner.java:427)
at org.testng.SuiteRunner.privateRun(SuiteRunner.java:387)
at org.testng.SuiteRunner.run(SuiteRunner.java:330)
at org.testng.SuiteRunnerWorker.runSuite(SuiteRunnerWorker.java:52)
at org.testng.SuiteRunnerWorker.run(SuiteRunnerWorker.java:95)
at org.testng.TestNG.runSuitesSequentially(TestNG.java:1256)
at org.testng.TestNG.runSuitesLocally(TestNG.java:1176)
at org.testng.TestNG.runSuites(TestNG.java:1099)
at org.testng.TestNG.run(TestNG.java:1067)
at org.testng.remote.AbstractRemoteTestNG.run(AbstractRemoteTestNG.java:115)
at org.testng.remote.RemoteTestNG.initAndRun(RemoteTestNG.java:251)
at org.testng.remote.RemoteTestNG.main(RemoteTestNG.java:77)
Caused by: groovy.json.JsonException: Lexing failed on line: 1, column: 1, while reading '<', no possible valid JSON value or punctuation could be recognized.
at groovy.json.JsonLexer.nextToken(JsonLexer.java:86)
at groovy.json.JsonLexer$nextToken.call(Unknown Source)
at org.codehaus.groovy.runtime.callsite.CallSiteArray.defaultCall(CallSiteArray.java:46)
at org.codehaus.groovy.runtime.callsite.AbstractCallSite.call(AbstractCallSite.java:125)
at org.codehaus.groovy.runtime.callsite.AbstractCallSite.call(AbstractCallSite.java:130)
at io.restassured.internal.path.json.ConfigurableJsonSlurper.parse(ConfigurableJsonSlurper.groovy:97)
at io.restassured.internal.path.json.ConfigurableJsonSlurper$parse.callCurrent(Unknown Source)
at org.codehaus.groovy.runtime.callsite.CallSiteArray.defaultCallCurrent(CallSiteArray.java:50)
at org.codehaus.groovy.runtime.callsite.AbstractCallSite.callCurrent(AbstractCallSite.java:171)
at org.codehaus.groovy.runtime.callsite.AbstractCallSite.callCurrent(AbstractCallSite.java:185)
at io.restassured.internal.path.json.ConfigurableJsonSlurper.parseText(ConfigurableJsonSlurper.groovy:83)
at io.restassured.path.json.JsonPath$4$1.method(JsonPath.java:965)
at io.restassured.path.json.JsonPath$ExceptionCatcher.invoke(JsonPath.java:1000)
... 30 more
]]>
            </full-stacktrace>
          </exception> <!-- io.restassured.path.json.exception.JsonPathException -->
          <reporter-output>
          </reporter-output>
        </test-method> <!-- checkContentType -->
        <test-method signature="checkResposeBody()[pri:0, instance:com.employeeapi.testCases.TC005_Delete_Employee_Record@7e07db1f]" started-at="2022-09-10T00:49:56 IST" name="checkResposeBody" finished-at="2022-09-10T00:49:56 IST" duration-ms="0" status="SKIP">
          <exception class="io.restassured.path.json.exception.JsonPathException">
            <message>
              <![CDATA[Failed to parse the JSON document]]>
            </message>
            <full-stacktrace>
              <![CDATA[io.restassured.path.json.exception.JsonPathException: Failed to parse the JSON document
at io.restassured.path.json.JsonPath$ExceptionCatcher.invoke(JsonPath.java:1002)
at io.restassured.path.json.JsonPath$4.doParseWith(JsonPath.java:967)
at io.restassured.path.json.JsonPath$JsonParser.parseWith(JsonPath.java:1047)
at io.restassured.path.json.JsonPath.get(JsonPath.java:202)
at com.employeeapi.testCases.TC005_Delete_Employee_Record.deleteEmployee(TC005_Delete_Employee_Record.java:46)
at java.base/jdk.internal.reflect.NativeMethodAccessorImpl.invoke0(Native Method)
at java.base/jdk.internal.reflect.NativeMethodAccessorImpl.invoke(NativeMethodAccessorImpl.java:77)
at java.base/jdk.internal.reflect.DelegatingMethodAccessorImpl.invoke(DelegatingMethodAccessorImpl.java:43)
at java.base/java.lang.reflect.Method.invoke(Method.java:568)
at org.testng.internal.invokers.MethodInvocationHelper.invokeMethod(MethodInvocationHelper.java:139)
at org.testng.internal.invokers.MethodInvocationHelper.invokeMethodConsideringTimeout(MethodInvocationHelper.java:69)
at org.testng.internal.invokers.ConfigInvoker.invokeConfigurationMethod(ConfigInvoker.java:361)
at org.testng.internal.invokers.ConfigInvoker.invokeConfigurations(ConfigInvoker.java:296)
at org.testng.internal.invokers.TestMethodWorker.invokeBeforeClassMethods(TestMethodWorker.java:180)
at org.testng.internal.invokers.TestMethodWorker.run(TestMethodWorker.java:122)
at java.base/java.util.ArrayList.forEach(ArrayList.java:1511)
at org.testng.TestRunner.privateRun(TestRunner.java:806)
at org.testng.TestRunner.run(TestRunner.java:601)
at org.testng.SuiteRunner.runTest(SuiteRunner.java:433)
at org.testng.SuiteRunner.runSequentially(SuiteRunner.java:427)
at org.testng.SuiteRunner.privateRun(SuiteRunner.java:387)
at org.testng.SuiteRunner.run(SuiteRunner.java:330)
at org.testng.SuiteRunnerWorker.runSuite(SuiteRunnerWorker.java:52)
at org.testng.SuiteRunnerWorker.run(SuiteRunnerWorker.java:95)
at org.testng.TestNG.runSuitesSequentially(TestNG.java:1256)
at org.testng.TestNG.runSuitesLocally(TestNG.java:1176)
at org.testng.TestNG.runSuites(TestNG.java:1099)
at org.testng.TestNG.run(TestNG.java:1067)
at org.testng.remote.AbstractRemoteTestNG.run(AbstractRemoteTestNG.java:115)
at org.testng.remote.RemoteTestNG.initAndRun(RemoteTestNG.java:251)
at org.testng.remote.RemoteTestNG.main(RemoteTestNG.java:77)
Caused by: groovy.json.JsonException: Lexing failed on line: 1, column: 1, while reading '<', no possible valid JSON value or punctuation could be recognized.
at groovy.json.JsonLexer.nextToken(JsonLexer.java:86)
at groovy.json.JsonLexer$nextToken.call(Unknown Source)
at org.codehaus.groovy.runtime.callsite.CallSiteArray.defaultCall(CallSiteArray.java:46)
at org.codehaus.groovy.runtime.callsite.AbstractCallSite.call(AbstractCallSite.java:125)
at org.codehaus.groovy.runtime.callsite.AbstractCallSite.call(AbstractCallSite.java:130)
at io.restassured.internal.path.json.ConfigurableJsonSlurper.parse(ConfigurableJsonSlurper.groovy:97)
at io.restassured.internal.path.json.ConfigurableJsonSlurper$parse.callCurrent(Unknown Source)
at org.codehaus.groovy.runtime.callsite.CallSiteArray.defaultCallCurrent(CallSiteArray.java:50)
at org.codehaus.groovy.runtime.callsite.AbstractCallSite.callCurrent(AbstractCallSite.java:171)
at org.codehaus.groovy.runtime.callsite.AbstractCallSite.callCurrent(AbstractCallSite.java:185)
at io.restassured.internal.path.json.ConfigurableJsonSlurper.parseText(ConfigurableJsonSlurper.groovy:83)
at io.restassured.path.json.JsonPath$4$1.method(JsonPath.java:965)
at io.restassured.path.json.JsonPath$ExceptionCatcher.invoke(JsonPath.java:1000)
... 30 more
]]>
            </full-stacktrace>
          </exception> <!-- io.restassured.path.json.exception.JsonPathException -->
          <reporter-output>
          </reporter-output>
        </test-method> <!-- checkResposeBody -->
        <test-method signature="checkStatusCode()[pri:0, instance:com.employeeapi.testCases.TC005_Delete_Employee_Record@7e07db1f]" started-at="2022-09-10T00:49:56 IST" name="checkStatusCode" finished-at="2022-09-10T00:49:56 IST" duration-ms="0" status="SKIP">
          <exception class="io.restassured.path.json.exception.JsonPathException">
            <message>
              <![CDATA[Failed to parse the JSON document]]>
            </message>
            <full-stacktrace>
              <![CDATA[io.restassured.path.json.exception.JsonPathException: Failed to parse the JSON document
at io.restassured.path.json.JsonPath$ExceptionCatcher.invoke(JsonPath.java:1002)
at io.restassured.path.json.JsonPath$4.doParseWith(JsonPath.java:967)
at io.restassured.path.json.JsonPath$JsonParser.parseWith(JsonPath.java:1047)
at io.restassured.path.json.JsonPath.get(JsonPath.java:202)
at com.employeeapi.testCases.TC005_Delete_Employee_Record.deleteEmployee(TC005_Delete_Employee_Record.java:46)
at java.base/jdk.internal.reflect.NativeMethodAccessorImpl.invoke0(Native Method)
at java.base/jdk.internal.reflect.NativeMethodAccessorImpl.invoke(NativeMethodAccessorImpl.java:77)
at java.base/jdk.internal.reflect.DelegatingMethodAccessorImpl.invoke(DelegatingMethodAccessorImpl.java:43)
at java.base/java.lang.reflect.Method.invoke(Method.java:568)
at org.testng.internal.invokers.MethodInvocationHelper.invokeMethod(MethodInvocationHelper.java:139)
at org.testng.internal.invokers.MethodInvocationHelper.invokeMethodConsideringTimeout(MethodInvocationHelper.java:69)
at org.testng.internal.invokers.ConfigInvoker.invokeConfigurationMethod(ConfigInvoker.java:361)
at org.testng.internal.invokers.ConfigInvoker.invokeConfigurations(ConfigInvoker.java:296)
at org.testng.internal.invokers.TestMethodWorker.invokeBeforeClassMethods(TestMethodWorker.java:180)
at org.testng.internal.invokers.TestMethodWorker.run(TestMethodWorker.java:122)
at java.base/java.util.ArrayList.forEach(ArrayList.java:1511)
at org.testng.TestRunner.privateRun(TestRunner.java:806)
at org.testng.TestRunner.run(TestRunner.java:601)
at org.testng.SuiteRunner.runTest(SuiteRunner.java:433)
at org.testng.SuiteRunner.runSequentially(SuiteRunner.java:427)
at org.testng.SuiteRunner.privateRun(SuiteRunner.java:387)
at org.testng.SuiteRunner.run(SuiteRunner.java:330)
at org.testng.SuiteRunnerWorker.runSuite(SuiteRunnerWorker.java:52)
at org.testng.SuiteRunnerWorker.run(SuiteRunnerWorker.java:95)
at org.testng.TestNG.runSuitesSequentially(TestNG.java:1256)
at org.testng.TestNG.runSuitesLocally(TestNG.java:1176)
at org.testng.TestNG.runSuites(TestNG.java:1099)
at org.testng.TestNG.run(TestNG.java:1067)
at org.testng.remote.AbstractRemoteTestNG.run(AbstractRemoteTestNG.java:115)
at org.testng.remote.RemoteTestNG.initAndRun(RemoteTestNG.java:251)
at org.testng.remote.RemoteTestNG.main(RemoteTestNG.java:77)
Caused by: groovy.json.JsonException: Lexing failed on line: 1, column: 1, while reading '<', no possible valid JSON value or punctuation could be recognized.
at groovy.json.JsonLexer.nextToken(JsonLexer.java:86)
at groovy.json.JsonLexer$nextToken.call(Unknown Source)
at org.codehaus.groovy.runtime.callsite.CallSiteArray.defaultCall(CallSiteArray.java:46)
at org.codehaus.groovy.runtime.callsite.AbstractCallSite.call(AbstractCallSite.java:125)
at org.codehaus.groovy.runtime.callsite.AbstractCallSite.call(AbstractCallSite.java:130)
at io.restassured.internal.path.json.ConfigurableJsonSlurper.parse(ConfigurableJsonSlurper.groovy:97)
at io.restassured.internal.path.json.ConfigurableJsonSlurper$parse.callCurrent(Unknown Source)
at org.codehaus.groovy.runtime.callsite.CallSiteArray.defaultCallCurrent(CallSiteArray.java:50)
at org.codehaus.groovy.runtime.callsite.AbstractCallSite.callCurrent(AbstractCallSite.java:171)
at org.codehaus.groovy.runtime.callsite.AbstractCallSite.callCurrent(AbstractCallSite.java:185)
at io.restassured.internal.path.json.ConfigurableJsonSlurper.parseText(ConfigurableJsonSlurper.groovy:83)
at io.restassured.path.json.JsonPath$4$1.method(JsonPath.java:965)
at io.restassured.path.json.JsonPath$ExceptionCatcher.invoke(JsonPath.java:1000)
... 30 more
]]>
            </full-stacktrace>
          </exception> <!-- io.restassured.path.json.exception.JsonPathException -->
          <reporter-output>
          </reporter-output>
        </test-method> <!-- checkStatusCode -->
        <test-method signature="checkcontentEncoding()[pri:0, instance:com.employeeapi.testCases.TC005_Delete_Employee_Record@7e07db1f]" started-at="2022-09-10T00:49:56 IST" name="checkcontentEncoding" finished-at="2022-09-10T00:49:56 IST" duration-ms="0" status="SKIP">
          <exception class="io.restassured.path.json.exception.JsonPathException">
            <message>
              <![CDATA[Failed to parse the JSON document]]>
            </message>
            <full-stacktrace>
              <![CDATA[io.restassured.path.json.exception.JsonPathException: Failed to parse the JSON document
at io.restassured.path.json.JsonPath$ExceptionCatcher.invoke(JsonPath.java:1002)
at io.restassured.path.json.JsonPath$4.doParseWith(JsonPath.java:967)
at io.restassured.path.json.JsonPath$JsonParser.parseWith(JsonPath.java:1047)
at io.restassured.path.json.JsonPath.get(JsonPath.java:202)
at com.employeeapi.testCases.TC005_Delete_Employee_Record.deleteEmployee(TC005_Delete_Employee_Record.java:46)
at java.base/jdk.internal.reflect.NativeMethodAccessorImpl.invoke0(Native Method)
at java.base/jdk.internal.reflect.NativeMethodAccessorImpl.invoke(NativeMethodAccessorImpl.java:77)
at java.base/jdk.internal.reflect.DelegatingMethodAccessorImpl.invoke(DelegatingMethodAccessorImpl.java:43)
at java.base/java.lang.reflect.Method.invoke(Method.java:568)
at org.testng.internal.invokers.MethodInvocationHelper.invokeMethod(MethodInvocationHelper.java:139)
at org.testng.internal.invokers.MethodInvocationHelper.invokeMethodConsideringTimeout(MethodInvocationHelper.java:69)
at org.testng.internal.invokers.ConfigInvoker.invokeConfigurationMethod(ConfigInvoker.java:361)
at org.testng.internal.invokers.ConfigInvoker.invokeConfigurations(ConfigInvoker.java:296)
at org.testng.internal.invokers.TestMethodWorker.invokeBeforeClassMethods(TestMethodWorker.java:180)
at org.testng.internal.invokers.TestMethodWorker.run(TestMethodWorker.java:122)
at java.base/java.util.ArrayList.forEach(ArrayList.java:1511)
at org.testng.TestRunner.privateRun(TestRunner.java:806)
at org.testng.TestRunner.run(TestRunner.java:601)
at org.testng.SuiteRunner.runTest(SuiteRunner.java:433)
at org.testng.SuiteRunner.runSequentially(SuiteRunner.java:427)
at org.testng.SuiteRunner.privateRun(SuiteRunner.java:387)
at org.testng.SuiteRunner.run(SuiteRunner.java:330)
at org.testng.SuiteRunnerWorker.runSuite(SuiteRunnerWorker.java:52)
at org.testng.SuiteRunnerWorker.run(SuiteRunnerWorker.java:95)
at org.testng.TestNG.runSuitesSequentially(TestNG.java:1256)
at org.testng.TestNG.runSuitesLocally(TestNG.java:1176)
at org.testng.TestNG.runSuites(TestNG.java:1099)
at org.testng.TestNG.run(TestNG.java:1067)
at org.testng.remote.AbstractRemoteTestNG.run(AbstractRemoteTestNG.java:115)
at org.testng.remote.RemoteTestNG.initAndRun(RemoteTestNG.java:251)
at org.testng.remote.RemoteTestNG.main(RemoteTestNG.java:77)
Caused by: groovy.json.JsonException: Lexing failed on line: 1, column: 1, while reading '<', no possible valid JSON value or punctuation could be recognized.
at groovy.json.JsonLexer.nextToken(JsonLexer.java:86)
at groovy.json.JsonLexer$nextToken.call(Unknown Source)
at org.codehaus.groovy.runtime.callsite.CallSiteArray.defaultCall(CallSiteArray.java:46)
at org.codehaus.groovy.runtime.callsite.AbstractCallSite.call(AbstractCallSite.java:125)
at org.codehaus.groovy.runtime.callsite.AbstractCallSite.call(AbstractCallSite.java:130)
at io.restassured.internal.path.json.ConfigurableJsonSlurper.parse(ConfigurableJsonSlurper.groovy:97)
at io.restassured.internal.path.json.ConfigurableJsonSlurper$parse.callCurrent(Unknown Source)
at org.codehaus.groovy.runtime.callsite.CallSiteArray.defaultCallCurrent(CallSiteArray.java:50)
at org.codehaus.groovy.runtime.callsite.AbstractCallSite.callCurrent(AbstractCallSite.java:171)
at org.codehaus.groovy.runtime.callsite.AbstractCallSite.callCurrent(AbstractCallSite.java:185)
at io.restassured.internal.path.json.ConfigurableJsonSlurper.parseText(ConfigurableJsonSlurper.groovy:83)
at io.restassured.path.json.JsonPath$4$1.method(JsonPath.java:965)
at io.restassured.path.json.JsonPath$ExceptionCatcher.invoke(JsonPath.java:1000)
... 30 more
]]>
            </full-stacktrace>
          </exception> <!-- io.restassured.path.json.exception.JsonPathException -->
          <reporter-output>
          </reporter-output>
        </test-method> <!-- checkcontentEncoding -->
        <test-method signature="checkserverType()[pri:0, instance:com.employeeapi.testCases.TC005_Delete_Employee_Record@7e07db1f]" started-at="2022-09-10T00:49:56 IST" name="checkserverType" finished-at="2022-09-10T00:49:56 IST" duration-ms="1" status="SKIP">
          <exception class="io.restassured.path.json.exception.JsonPathException">
            <message>
              <![CDATA[Failed to parse the JSON document]]>
            </message>
            <full-stacktrace>
              <![CDATA[io.restassured.path.json.exception.JsonPathException: Failed to parse the JSON document
at io.restassured.path.json.JsonPath$ExceptionCatcher.invoke(JsonPath.java:1002)
at io.restassured.path.json.JsonPath$4.doParseWith(JsonPath.java:967)
at io.restassured.path.json.JsonPath$JsonParser.parseWith(JsonPath.java:1047)
at io.restassured.path.json.JsonPath.get(JsonPath.java:202)
at com.employeeapi.testCases.TC005_Delete_Employee_Record.deleteEmployee(TC005_Delete_Employee_Record.java:46)
at java.base/jdk.internal.reflect.NativeMethodAccessorImpl.invoke0(Native Method)
at java.base/jdk.internal.reflect.NativeMethodAccessorImpl.invoke(NativeMethodAccessorImpl.java:77)
at java.base/jdk.internal.reflect.DelegatingMethodAccessorImpl.invoke(DelegatingMethodAccessorImpl.java:43)
at java.base/java.lang.reflect.Method.invoke(Method.java:568)
at org.testng.internal.invokers.MethodInvocationHelper.invokeMethod(MethodInvocationHelper.java:139)
at org.testng.internal.invokers.MethodInvocationHelper.invokeMethodConsideringTimeout(MethodInvocationHelper.java:69)
at org.testng.internal.invokers.ConfigInvoker.invokeConfigurationMethod(ConfigInvoker.java:361)
at org.testng.internal.invokers.ConfigInvoker.invokeConfigurations(ConfigInvoker.java:296)
at org.testng.internal.invokers.TestMethodWorker.invokeBeforeClassMethods(TestMethodWorker.java:180)
at org.testng.internal.invokers.TestMethodWorker.run(TestMethodWorker.java:122)
at java.base/java.util.ArrayList.forEach(ArrayList.java:1511)
at org.testng.TestRunner.privateRun(TestRunner.java:806)
at org.testng.TestRunner.run(TestRunner.java:601)
at org.testng.SuiteRunner.runTest(SuiteRunner.java:433)
at org.testng.SuiteRunner.runSequentially(SuiteRunner.java:427)
at org.testng.SuiteRunner.privateRun(SuiteRunner.java:387)
at org.testng.SuiteRunner.run(SuiteRunner.java:330)
at org.testng.SuiteRunnerWorker.runSuite(SuiteRunnerWorker.java:52)
at org.testng.SuiteRunnerWorker.run(SuiteRunnerWorker.java:95)
at org.testng.TestNG.runSuitesSequentially(TestNG.java:1256)
at org.testng.TestNG.runSuitesLocally(TestNG.java:1176)
at org.testng.TestNG.runSuites(TestNG.java:1099)
at org.testng.TestNG.run(TestNG.java:1067)
at org.testng.remote.AbstractRemoteTestNG.run(AbstractRemoteTestNG.java:115)
at org.testng.remote.RemoteTestNG.initAndRun(RemoteTestNG.java:251)
at org.testng.remote.RemoteTestNG.main(RemoteTestNG.java:77)
Caused by: groovy.json.JsonException: Lexing failed on line: 1, column: 1, while reading '<', no possible valid JSON value or punctuation could be recognized.
at groovy.json.JsonLexer.nextToken(JsonLexer.java:86)
at groovy.json.JsonLexer$nextToken.call(Unknown Source)
at org.codehaus.groovy.runtime.callsite.CallSiteArray.defaultCall(CallSiteArray.java:46)
at org.codehaus.groovy.runtime.callsite.AbstractCallSite.call(AbstractCallSite.java:125)
at org.codehaus.groovy.runtime.callsite.AbstractCallSite.call(AbstractCallSite.java:130)
at io.restassured.internal.path.json.ConfigurableJsonSlurper.parse(ConfigurableJsonSlurper.groovy:97)
at io.restassured.internal.path.json.ConfigurableJsonSlurper$parse.callCurrent(Unknown Source)
at org.codehaus.groovy.runtime.callsite.CallSiteArray.defaultCallCurrent(CallSiteArray.java:50)
at org.codehaus.groovy.runtime.callsite.AbstractCallSite.callCurrent(AbstractCallSite.java:171)
at org.codehaus.groovy.runtime.callsite.AbstractCallSite.callCurrent(AbstractCallSite.java:185)
at io.restassured.internal.path.json.ConfigurableJsonSlurper.parseText(ConfigurableJsonSlurper.groovy:83)
at io.restassured.path.json.JsonPath$4$1.method(JsonPath.java:965)
at io.restassured.path.json.JsonPath$ExceptionCatcher.invoke(JsonPath.java:1000)
... 30 more
]]>
            </full-stacktrace>
          </exception> <!-- io.restassured.path.json.exception.JsonPathException -->
          <reporter-output>
          </reporter-output>
        </test-method> <!-- checkserverType -->
        <test-method signature="checkstatusLine()[pri:0, instance:com.employeeapi.testCases.TC005_Delete_Employee_Record@7e07db1f]" started-at="2022-09-10T00:49:56 IST" name="checkstatusLine" finished-at="2022-09-10T00:49:56 IST" duration-ms="0" status="SKIP">
          <exception class="io.restassured.path.json.exception.JsonPathException">
            <message>
              <![CDATA[Failed to parse the JSON document]]>
            </message>
            <full-stacktrace>
              <![CDATA[io.restassured.path.json.exception.JsonPathException: Failed to parse the JSON document
at io.restassured.path.json.JsonPath$ExceptionCatcher.invoke(JsonPath.java:1002)
at io.restassured.path.json.JsonPath$4.doParseWith(JsonPath.java:967)
at io.restassured.path.json.JsonPath$JsonParser.parseWith(JsonPath.java:1047)
at io.restassured.path.json.JsonPath.get(JsonPath.java:202)
at com.employeeapi.testCases.TC005_Delete_Employee_Record.deleteEmployee(TC005_Delete_Employee_Record.java:46)
at java.base/jdk.internal.reflect.NativeMethodAccessorImpl.invoke0(Native Method)
at java.base/jdk.internal.reflect.NativeMethodAccessorImpl.invoke(NativeMethodAccessorImpl.java:77)
at java.base/jdk.internal.reflect.DelegatingMethodAccessorImpl.invoke(DelegatingMethodAccessorImpl.java:43)
at java.base/java.lang.reflect.Method.invoke(Method.java:568)
at org.testng.internal.invokers.MethodInvocationHelper.invokeMethod(MethodInvocationHelper.java:139)
at org.testng.internal.invokers.MethodInvocationHelper.invokeMethodConsideringTimeout(MethodInvocationHelper.java:69)
at org.testng.internal.invokers.ConfigInvoker.invokeConfigurationMethod(ConfigInvoker.java:361)
at org.testng.internal.invokers.ConfigInvoker.invokeConfigurations(ConfigInvoker.java:296)
at org.testng.internal.invokers.TestMethodWorker.invokeBeforeClassMethods(TestMethodWorker.java:180)
at org.testng.internal.invokers.TestMethodWorker.run(TestMethodWorker.java:122)
at java.base/java.util.ArrayList.forEach(ArrayList.java:1511)
at org.testng.TestRunner.privateRun(TestRunner.java:806)
at org.testng.TestRunner.run(TestRunner.java:601)
at org.testng.SuiteRunner.runTest(SuiteRunner.java:433)
at org.testng.SuiteRunner.runSequentially(SuiteRunner.java:427)
at org.testng.SuiteRunner.privateRun(SuiteRunner.java:387)
at org.testng.SuiteRunner.run(SuiteRunner.java:330)
at org.testng.SuiteRunnerWorker.runSuite(SuiteRunnerWorker.java:52)
at org.testng.SuiteRunnerWorker.run(SuiteRunnerWorker.java:95)
at org.testng.TestNG.runSuitesSequentially(TestNG.java:1256)
at org.testng.TestNG.runSuitesLocally(TestNG.java:1176)
at org.testng.TestNG.runSuites(TestNG.java:1099)
at org.testng.TestNG.run(TestNG.java:1067)
at org.testng.remote.AbstractRemoteTestNG.run(AbstractRemoteTestNG.java:115)
at org.testng.remote.RemoteTestNG.initAndRun(RemoteTestNG.java:251)
at org.testng.remote.RemoteTestNG.main(RemoteTestNG.java:77)
Caused by: groovy.json.JsonException: Lexing failed on line: 1, column: 1, while reading '<', no possible valid JSON value or punctuation could be recognized.
at groovy.json.JsonLexer.nextToken(JsonLexer.java:86)
at groovy.json.JsonLexer$nextToken.call(Unknown Source)
at org.codehaus.groovy.runtime.callsite.CallSiteArray.defaultCall(CallSiteArray.java:46)
at org.codehaus.groovy.runtime.callsite.AbstractCallSite.call(AbstractCallSite.java:125)
at org.codehaus.groovy.runtime.callsite.AbstractCallSite.call(AbstractCallSite.java:130)
at io.restassured.internal.path.json.ConfigurableJsonSlurper.parse(ConfigurableJsonSlurper.groovy:97)
at io.restassured.internal.path.json.ConfigurableJsonSlurper$parse.callCurrent(Unknown Source)
at org.codehaus.groovy.runtime.callsite.CallSiteArray.defaultCallCurrent(CallSiteArray.java:50)
at org.codehaus.groovy.runtime.callsite.AbstractCallSite.callCurrent(AbstractCallSite.java:171)
at org.codehaus.groovy.runtime.callsite.AbstractCallSite.callCurrent(AbstractCallSite.java:185)
at io.restassured.internal.path.json.ConfigurableJsonSlurper.parseText(ConfigurableJsonSlurper.groovy:83)
at io.restassured.path.json.JsonPath$4$1.method(JsonPath.java:965)
at io.restassured.path.json.JsonPath$ExceptionCatcher.invoke(JsonPath.java:1000)
... 30 more
]]>
            </full-stacktrace>
          </exception> <!-- io.restassured.path.json.exception.JsonPathException -->
          <reporter-output>
          </reporter-output>
        </test-method> <!-- checkstatusLine -->
        <test-method is-config="true" signature="tearDown()[pri:0, instance:com.employeeapi.testCases.TC005_Delete_Employee_Record@7e07db1f]" started-at="2022-09-10T00:49:56 IST" name="tearDown" finished-at="2022-09-10T00:49:56 IST" duration-ms="0" status="SKIP">
          <reporter-output>
          </reporter-output>
        </test-method> <!-- tearDown -->
      </class> <!-- com.employeeapi.testCases.TC005_Delete_Employee_Record -->
      <class name="com.employeeapi.testCases.TC001_Get_All_Employees">
        <test-method is-config="true" signature="setup()[pri:0, instance:com.employeeapi.testCases.TC001_Get_All_Employees@2a798d51]" started-at="2022-09-10T00:49:31 IST" name="setup" finished-at="2022-09-10T00:49:31 IST" duration-ms="57" status="PASS">
          <reporter-output>
          </reporter-output>
        </test-method> <!-- setup -->
        <test-method is-config="true" signature="getAllEmployees()[pri:0, instance:com.employeeapi.testCases.TC001_Get_All_Employees@2a798d51]" started-at="2022-09-10T00:49:31 IST" name="getAllEmployees" finished-at="2022-09-10T00:49:34 IST" duration-ms="2793" status="PASS">
          <reporter-output>
          </reporter-output>
        </test-method> <!-- getAllEmployees -->
        <test-method signature="checkContentLenght()[pri:0, instance:com.employeeapi.testCases.TC001_Get_All_Employees@2a798d51]" started-at="2022-09-10T00:49:34 IST" name="checkContentLenght" finished-at="2022-09-10T00:49:34 IST" duration-ms="10" status="FAIL">
          <exception class="java.lang.NumberFormatException">
            <message>
              <![CDATA[Cannot parse null string]]>
            </message>
            <full-stacktrace>
              <![CDATA[java.lang.NumberFormatException: Cannot parse null string
at java.base/java.lang.Integer.parseInt(Integer.java:630)
at java.base/java.lang.Integer.parseInt(Integer.java:786)
at com.employeeapi.testCases.TC001_Get_All_Employees.checkContentLenght(TC001_Get_All_Employees.java:121)
at java.base/jdk.internal.reflect.NativeMethodAccessorImpl.invoke0(Native Method)
at java.base/jdk.internal.reflect.NativeMethodAccessorImpl.invoke(NativeMethodAccessorImpl.java:77)
at java.base/jdk.internal.reflect.DelegatingMethodAccessorImpl.invoke(DelegatingMethodAccessorImpl.java:43)
at java.base/java.lang.reflect.Method.invoke(Method.java:568)
at org.testng.internal.invokers.MethodInvocationHelper.invokeMethod(MethodInvocationHelper.java:139)
at org.testng.internal.invokers.TestInvoker.invokeMethod(TestInvoker.java:677)
at org.testng.internal.invokers.TestInvoker.invokeTestMethod(TestInvoker.java:221)
at org.testng.internal.invokers.MethodRunner.runInSequence(MethodRunner.java:50)
at org.testng.internal.invokers.TestInvoker$MethodInvocationAgent.invoke(TestInvoker.java:962)
at org.testng.internal.invokers.TestInvoker.invokeTestMethods(TestInvoker.java:194)
at org.testng.internal.invokers.TestMethodWorker.invokeTestMethods(TestMethodWorker.java:148)
at org.testng.internal.invokers.TestMethodWorker.run(TestMethodWorker.java:128)
at java.base/java.util.ArrayList.forEach(ArrayList.java:1511)
at org.testng.TestRunner.privateRun(TestRunner.java:806)
at org.testng.TestRunner.run(TestRunner.java:601)
at org.testng.SuiteRunner.runTest(SuiteRunner.java:433)
at org.testng.SuiteRunner.runSequentially(SuiteRunner.java:427)
at org.testng.SuiteRunner.privateRun(SuiteRunner.java:387)
at org.testng.SuiteRunner.run(SuiteRunner.java:330)
at org.testng.SuiteRunnerWorker.runSuite(SuiteRunnerWorker.java:52)
at org.testng.SuiteRunnerWorker.run(SuiteRunnerWorker.java:95)
at org.testng.TestNG.runSuitesSequentially(TestNG.java:1256)
at org.testng.TestNG.runSuitesLocally(TestNG.java:1176)
at org.testng.TestNG.runSuites(TestNG.java:1099)
at org.testng.TestNG.run(TestNG.java:1067)
at org.testng.remote.AbstractRemoteTestNG.run(AbstractRemoteTestNG.java:115)
at org.testng.remote.RemoteTestNG.initAndRun(RemoteTestNG.java:251)
at org.testng.remote.RemoteTestNG.main(RemoteTestNG.java:77)
]]>
            </full-stacktrace>
          </exception> <!-- java.lang.NumberFormatException -->
          <reporter-output>
          </reporter-output>
        </test-method> <!-- checkContentLenght -->
        <test-method signature="checkContentType()[pri:0, instance:com.employeeapi.testCases.TC001_Get_All_Employees@2a798d51]" started-at="2022-09-10T00:49:34 IST" name="checkContentType" finished-at="2022-09-10T00:49:34 IST" duration-ms="15" status="PASS">
          <reporter-output>
          </reporter-output>
        </test-method> <!-- checkContentType -->
        <test-method signature="checkCookies()[pri:0, instance:com.employeeapi.testCases.TC001_Get_All_Employees@2a798d51]" started-at="2022-09-10T00:49:34 IST" name="checkCookies" finished-at="2022-09-10T00:49:34 IST" duration-ms="7" status="PASS">
          <reporter-output>
          </reporter-output>
        </test-method> <!-- checkCookies -->
        <test-method signature="checkResponseTime()[pri:0, instance:com.employeeapi.testCases.TC001_Get_All_Employees@2a798d51]" started-at="2022-09-10T00:49:34 IST" name="checkResponseTime" finished-at="2022-09-10T00:49:34 IST" duration-ms="8" status="PASS">
          <reporter-output>
          </reporter-output>
        </test-method> <!-- checkResponseTime -->
        <test-method signature="checkResposeBody()[pri:0, instance:com.employeeapi.testCases.TC001_Get_All_Employees@2a798d51]" started-at="2022-09-10T00:49:34 IST" name="checkResposeBody" finished-at="2022-09-10T00:49:34 IST" duration-ms="43" status="PASS">
          <reporter-output>
          </reporter-output>
        </test-method> <!-- checkResposeBody -->
        <test-method signature="checkStatusCode()[pri:0, instance:com.employeeapi.testCases.TC001_Get_All_Employees@2a798d51]" started-at="2022-09-10T00:49:34 IST" name="checkStatusCode" finished-at="2022-09-10T00:49:34 IST" duration-ms="23" status="FAIL">
          <exception class="java.lang.AssertionError">
            <message>
              <![CDATA[expected [200] but found [429]]]>
            </message>
            <full-stacktrace>
              <![CDATA[java.lang.AssertionError: expected [200] but found [429]
at org.testng.Assert.fail(Assert.java:110)
at org.testng.Assert.failNotEquals(Assert.java:1413)
at org.testng.Assert.assertEqualsImpl(Assert.java:149)
at org.testng.Assert.assertEquals(Assert.java:131)
at org.testng.Assert.assertEquals(Assert.java:1240)
at org.testng.Assert.assertEquals(Assert.java:1274)
at com.employeeapi.testCases.TC001_Get_All_Employees.checkStatusCode(TC001_Get_All_Employees.java:57)
at java.base/jdk.internal.reflect.NativeMethodAccessorImpl.invoke0(Native Method)
at java.base/jdk.internal.reflect.NativeMethodAccessorImpl.invoke(NativeMethodAccessorImpl.java:77)
at java.base/jdk.internal.reflect.DelegatingMethodAccessorImpl.invoke(DelegatingMethodAccessorImpl.java:43)
at java.base/java.lang.reflect.Method.invoke(Method.java:568)
at org.testng.internal.invokers.MethodInvocationHelper.invokeMethod(MethodInvocationHelper.java:139)
at org.testng.internal.invokers.TestInvoker.invokeMethod(TestInvoker.java:677)
at org.testng.internal.invokers.TestInvoker.invokeTestMethod(TestInvoker.java:221)
at org.testng.internal.invokers.MethodRunner.runInSequence(MethodRunner.java:50)
at org.testng.internal.invokers.TestInvoker$MethodInvocationAgent.invoke(TestInvoker.java:962)
at org.testng.internal.invokers.TestInvoker.invokeTestMethods(TestInvoker.java:194)
at org.testng.internal.invokers.TestMethodWorker.invokeTestMethods(TestMethodWorker.java:148)
at org.testng.internal.invokers.TestMethodWorker.run(TestMethodWorker.java:128)
at java.base/java.util.ArrayList.forEach(ArrayList.java:1511)
at org.testng.TestRunner.privateRun(TestRunner.java:806)
at org.testng.TestRunner.run(TestRunner.java:601)
at org.testng.SuiteRunner.runTest(SuiteRunner.java:433)
at org.testng.SuiteRunner.runSequentially(SuiteRunner.java:427)
at org.testng.SuiteRunner.privateRun(SuiteRunner.java:387)
at org.testng.SuiteRunner.run(SuiteRunner.java:330)
at org.testng.SuiteRunnerWorker.runSuite(SuiteRunnerWorker.java:52)
at org.testng.SuiteRunnerWorker.run(SuiteRunnerWorker.java:95)
at org.testng.TestNG.runSuitesSequentially(TestNG.java:1256)
at org.testng.TestNG.runSuitesLocally(TestNG.java:1176)
at org.testng.TestNG.runSuites(TestNG.java:1099)
at org.testng.TestNG.run(TestNG.java:1067)
at org.testng.remote.AbstractRemoteTestNG.run(AbstractRemoteTestNG.java:115)
at org.testng.remote.RemoteTestNG.initAndRun(RemoteTestNG.java:251)
at org.testng.remote.RemoteTestNG.main(RemoteTestNG.java:77)
]]>
            </full-stacktrace>
          </exception> <!-- java.lang.AssertionError -->
          <reporter-output>
          </reporter-output>
        </test-method> <!-- checkStatusCode -->
        <test-method signature="checkcontentEncoding()[pri:0, instance:com.employeeapi.testCases.TC001_Get_All_Employees@2a798d51]" started-at="2022-09-10T00:49:34 IST" name="checkcontentEncoding" finished-at="2022-09-10T00:49:34 IST" duration-ms="6" status="PASS">
          <reporter-output>
          </reporter-output>
        </test-method> <!-- checkcontentEncoding -->
        <test-method signature="checkserverType()[pri:0, instance:com.employeeapi.testCases.TC001_Get_All_Employees@2a798d51]" started-at="2022-09-10T00:49:34 IST" name="checkserverType" finished-at="2022-09-10T00:49:34 IST" duration-ms="12" status="FAIL">
          <exception class="java.lang.AssertionError">
            <message>
              <![CDATA[expected [nginx/1.14.1] but found [nginx]]]>
            </message>
            <full-stacktrace>
              <![CDATA[java.lang.AssertionError: expected [nginx/1.14.1] but found [nginx]
at org.testng.Assert.fail(Assert.java:110)
at org.testng.Assert.failNotEquals(Assert.java:1413)
at org.testng.Assert.assertEqualsImpl(Assert.java:149)
at org.testng.Assert.assertEquals(Assert.java:131)
at org.testng.Assert.assertEquals(Assert.java:655)
at org.testng.Assert.assertEquals(Assert.java:665)
at com.employeeapi.testCases.TC001_Get_All_Employees.checkserverType(TC001_Get_All_Employees.java:100)
at java.base/jdk.internal.reflect.NativeMethodAccessorImpl.invoke0(Native Method)
at java.base/jdk.internal.reflect.NativeMethodAccessorImpl.invoke(NativeMethodAccessorImpl.java:77)
at java.base/jdk.internal.reflect.DelegatingMethodAccessorImpl.invoke(DelegatingMethodAccessorImpl.java:43)
at java.base/java.lang.reflect.Method.invoke(Method.java:568)
at org.testng.internal.invokers.MethodInvocationHelper.invokeMethod(MethodInvocationHelper.java:139)
at org.testng.internal.invokers.TestInvoker.invokeMethod(TestInvoker.java:677)
at org.testng.internal.invokers.TestInvoker.invokeTestMethod(TestInvoker.java:221)
at org.testng.internal.invokers.MethodRunner.runInSequence(MethodRunner.java:50)
at org.testng.internal.invokers.TestInvoker$MethodInvocationAgent.invoke(TestInvoker.java:962)
at org.testng.internal.invokers.TestInvoker.invokeTestMethods(TestInvoker.java:194)
at org.testng.internal.invokers.TestMethodWorker.invokeTestMethods(TestMethodWorker.java:148)
at org.testng.internal.invokers.TestMethodWorker.run(TestMethodWorker.java:128)
at java.base/java.util.ArrayList.forEach(ArrayList.java:1511)
at org.testng.TestRunner.privateRun(TestRunner.java:806)
at org.testng.TestRunner.run(TestRunner.java:601)
at org.testng.SuiteRunner.runTest(SuiteRunner.java:433)
at org.testng.SuiteRunner.runSequentially(SuiteRunner.java:427)
at org.testng.SuiteRunner.privateRun(SuiteRunner.java:387)
at org.testng.SuiteRunner.run(SuiteRunner.java:330)
at org.testng.SuiteRunnerWorker.runSuite(SuiteRunnerWorker.java:52)
at org.testng.SuiteRunnerWorker.run(SuiteRunnerWorker.java:95)
at org.testng.TestNG.runSuitesSequentially(TestNG.java:1256)
at org.testng.TestNG.runSuitesLocally(TestNG.java:1176)
at org.testng.TestNG.runSuites(TestNG.java:1099)
at org.testng.TestNG.run(TestNG.java:1067)
at org.testng.remote.AbstractRemoteTestNG.run(AbstractRemoteTestNG.java:115)
at org.testng.remote.RemoteTestNG.initAndRun(RemoteTestNG.java:251)
at org.testng.remote.RemoteTestNG.main(RemoteTestNG.java:77)
]]>
            </full-stacktrace>
          </exception> <!-- java.lang.AssertionError -->
          <reporter-output>
          </reporter-output>
        </test-method> <!-- checkserverType -->
        <test-method signature="checkstatusLine()[pri:0, instance:com.employeeapi.testCases.TC001_Get_All_Employees@2a798d51]" started-at="2022-09-10T00:49:34 IST" name="checkstatusLine" finished-at="2022-09-10T00:49:34 IST" duration-ms="11" status="FAIL">
          <exception class="java.lang.AssertionError">
            <message>
              <![CDATA[expected [HTTP/1.1 200 OK] but found [HTTP/1.1 429 Too Many Requests]]]>
            </message>
            <full-stacktrace>
              <![CDATA[java.lang.AssertionError: expected [HTTP/1.1 200 OK] but found [HTTP/1.1 429 Too Many Requests]
at org.testng.Assert.fail(Assert.java:110)
at org.testng.Assert.failNotEquals(Assert.java:1413)
at org.testng.Assert.assertEqualsImpl(Assert.java:149)
at org.testng.Assert.assertEquals(Assert.java:131)
at org.testng.Assert.assertEquals(Assert.java:655)
at org.testng.Assert.assertEquals(Assert.java:665)
at com.employeeapi.testCases.TC001_Get_All_Employees.checkstatusLine(TC001_Get_All_Employees.java:81)
at java.base/jdk.internal.reflect.NativeMethodAccessorImpl.invoke0(Native Method)
at java.base/jdk.internal.reflect.NativeMethodAccessorImpl.invoke(NativeMethodAccessorImpl.java:77)
at java.base/jdk.internal.reflect.DelegatingMethodAccessorImpl.invoke(DelegatingMethodAccessorImpl.java:43)
at java.base/java.lang.reflect.Method.invoke(Method.java:568)
at org.testng.internal.invokers.MethodInvocationHelper.invokeMethod(MethodInvocationHelper.java:139)
at org.testng.internal.invokers.TestInvoker.invokeMethod(TestInvoker.java:677)
at org.testng.internal.invokers.TestInvoker.invokeTestMethod(TestInvoker.java:221)
at org.testng.internal.invokers.MethodRunner.runInSequence(MethodRunner.java:50)
at org.testng.internal.invokers.TestInvoker$MethodInvocationAgent.invoke(TestInvoker.java:962)
at org.testng.internal.invokers.TestInvoker.invokeTestMethods(TestInvoker.java:194)
at org.testng.internal.invokers.TestMethodWorker.invokeTestMethods(TestMethodWorker.java:148)
at org.testng.internal.invokers.TestMethodWorker.run(TestMethodWorker.java:128)
at java.base/java.util.ArrayList.forEach(ArrayList.java:1511)
at org.testng.TestRunner.privateRun(TestRunner.java:806)
at org.testng.TestRunner.run(TestRunner.java:601)
at org.testng.SuiteRunner.runTest(SuiteRunner.java:433)
at org.testng.SuiteRunner.runSequentially(SuiteRunner.java:427)
at org.testng.SuiteRunner.privateRun(SuiteRunner.java:387)
at org.testng.SuiteRunner.run(SuiteRunner.java:330)
at org.testng.SuiteRunnerWorker.runSuite(SuiteRunnerWorker.java:52)
at org.testng.SuiteRunnerWorker.run(SuiteRunnerWorker.java:95)
at org.testng.TestNG.runSuitesSequentially(TestNG.java:1256)
at org.testng.TestNG.runSuitesLocally(TestNG.java:1176)
at org.testng.TestNG.runSuites(TestNG.java:1099)
at org.testng.TestNG.run(TestNG.java:1067)
at org.testng.remote.AbstractRemoteTestNG.run(AbstractRemoteTestNG.java:115)
at org.testng.remote.RemoteTestNG.initAndRun(RemoteTestNG.java:251)
at org.testng.remote.RemoteTestNG.main(RemoteTestNG.java:77)
]]>
            </full-stacktrace>
          </exception> <!-- java.lang.AssertionError -->
          <reporter-output>
          </reporter-output>
        </test-method> <!-- checkstatusLine -->
        <test-method is-config="true" signature="tearDown()[pri:0, instance:com.employeeapi.testCases.TC001_Get_All_Employees@2a798d51]" started-at="2022-09-10T00:49:34 IST" name="tearDown" finished-at="2022-09-10T00:49:34 IST" duration-ms="3" status="PASS">
          <reporter-output>
          </reporter-output>
        </test-method> <!-- tearDown -->
      </class> <!-- com.employeeapi.testCases.TC001_Get_All_Employees -->
      <class name="com.employeeapi.testCases.TC004_Put_Employee_Record">
        <test-method is-config="true" signature="setup()[pri:0, instance:com.employeeapi.testCases.TC004_Put_Employee_Record@3a93b025]" started-at="2022-09-10T00:49:48 IST" name="setup" finished-at="2022-09-10T00:49:48 IST" duration-ms="3" status="PASS">
          <reporter-output>
          </reporter-output>
        </test-method> <!-- setup -->
        <test-method is-config="true" signature="updateEmployee()[pri:0, instance:com.employeeapi.testCases.TC004_Put_Employee_Record@3a93b025]" started-at="2022-09-10T00:49:48 IST" name="updateEmployee" finished-at="2022-09-10T00:49:55 IST" duration-ms="6782" status="PASS">
          <reporter-output>
          </reporter-output>
        </test-method> <!-- updateEmployee -->
        <test-method signature="checkContentType()[pri:0, instance:com.employeeapi.testCases.TC004_Put_Employee_Record@3a93b025]" started-at="2022-09-10T00:49:55 IST" name="checkContentType" finished-at="2022-09-10T00:49:55 IST" duration-ms="5" status="FAIL">
          <exception class="java.lang.AssertionError">
            <message>
              <![CDATA[expected [text/html; charset=UTF-8] but found [application/json]]]>
            </message>
            <full-stacktrace>
              <![CDATA[java.lang.AssertionError: expected [text/html; charset=UTF-8] but found [application/json]
at org.testng.Assert.fail(Assert.java:110)
at org.testng.Assert.failNotEquals(Assert.java:1413)
at org.testng.Assert.assertEqualsImpl(Assert.java:149)
at org.testng.Assert.assertEquals(Assert.java:131)
at org.testng.Assert.assertEquals(Assert.java:655)
at org.testng.Assert.assertEquals(Assert.java:665)
at com.employeeapi.testCases.TC004_Put_Employee_Record.checkContentType(TC004_Put_Employee_Record.java:89)
at java.base/jdk.internal.reflect.NativeMethodAccessorImpl.invoke0(Native Method)
at java.base/jdk.internal.reflect.NativeMethodAccessorImpl.invoke(NativeMethodAccessorImpl.java:77)
at java.base/jdk.internal.reflect.DelegatingMethodAccessorImpl.invoke(DelegatingMethodAccessorImpl.java:43)
at java.base/java.lang.reflect.Method.invoke(Method.java:568)
at org.testng.internal.invokers.MethodInvocationHelper.invokeMethod(MethodInvocationHelper.java:139)
at org.testng.internal.invokers.TestInvoker.invokeMethod(TestInvoker.java:677)
at org.testng.internal.invokers.TestInvoker.invokeTestMethod(TestInvoker.java:221)
at org.testng.internal.invokers.MethodRunner.runInSequence(MethodRunner.java:50)
at org.testng.internal.invokers.TestInvoker$MethodInvocationAgent.invoke(TestInvoker.java:962)
at org.testng.internal.invokers.TestInvoker.invokeTestMethods(TestInvoker.java:194)
at org.testng.internal.invokers.TestMethodWorker.invokeTestMethods(TestMethodWorker.java:148)
at org.testng.internal.invokers.TestMethodWorker.run(TestMethodWorker.java:128)
at java.base/java.util.ArrayList.forEach(ArrayList.java:1511)
at org.testng.TestRunner.privateRun(TestRunner.java:806)
at org.testng.TestRunner.run(TestRunner.java:601)
at org.testng.SuiteRunner.runTest(SuiteRunner.java:433)
at org.testng.SuiteRunner.runSequentially(SuiteRunner.java:427)
at org.testng.SuiteRunner.privateRun(SuiteRunner.java:387)
at org.testng.SuiteRunner.run(SuiteRunner.java:330)
at org.testng.SuiteRunnerWorker.runSuite(SuiteRunnerWorker.java:52)
at org.testng.SuiteRunnerWorker.run(SuiteRunnerWorker.java:95)
at org.testng.TestNG.runSuitesSequentially(TestNG.java:1256)
at org.testng.TestNG.runSuitesLocally(TestNG.java:1176)
at org.testng.TestNG.runSuites(TestNG.java:1099)
at org.testng.TestNG.run(TestNG.java:1067)
at org.testng.remote.AbstractRemoteTestNG.run(AbstractRemoteTestNG.java:115)
at org.testng.remote.RemoteTestNG.initAndRun(RemoteTestNG.java:251)
at org.testng.remote.RemoteTestNG.main(RemoteTestNG.java:77)
]]>
            </full-stacktrace>
          </exception> <!-- java.lang.AssertionError -->
          <reporter-output>
          </reporter-output>
        </test-method> <!-- checkContentType -->
        <test-method signature="checkResposeBody()[pri:0, instance:com.employeeapi.testCases.TC004_Put_Employee_Record@3a93b025]" started-at="2022-09-10T00:49:55 IST" name="checkResposeBody" finished-at="2022-09-10T00:49:55 IST" duration-ms="12" status="PASS">
          <reporter-output>
          </reporter-output>
        </test-method> <!-- checkResposeBody -->
        <test-method signature="checkStatusCode()[pri:0, instance:com.employeeapi.testCases.TC004_Put_Employee_Record@3a93b025]" started-at="2022-09-10T00:49:55 IST" name="checkStatusCode" finished-at="2022-09-10T00:49:55 IST" duration-ms="6" status="PASS">
          <reporter-output>
          </reporter-output>
        </test-method> <!-- checkStatusCode -->
        <test-method signature="checkcontentEncoding()[pri:0, instance:com.employeeapi.testCases.TC004_Put_Employee_Record@3a93b025]" started-at="2022-09-10T00:49:55 IST" name="checkcontentEncoding" finished-at="2022-09-10T00:49:55 IST" duration-ms="4" status="FAIL">
          <exception class="java.lang.AssertionError">
            <message>
              <![CDATA[expected [gzip] but found [null]]]>
            </message>
            <full-stacktrace>
              <![CDATA[java.lang.AssertionError: expected [gzip] but found [null]
at org.testng.Assert.fail(Assert.java:110)
at org.testng.Assert.failNotEquals(Assert.java:1413)
at org.testng.Assert.assertEqualsImpl(Assert.java:149)
at org.testng.Assert.assertEquals(Assert.java:131)
at org.testng.Assert.assertEquals(Assert.java:655)
at org.testng.Assert.assertEquals(Assert.java:665)
at com.employeeapi.testCases.TC004_Put_Employee_Record.checkcontentEncoding(TC004_Put_Employee_Record.java:101)
at java.base/jdk.internal.reflect.NativeMethodAccessorImpl.invoke0(Native Method)
at java.base/jdk.internal.reflect.NativeMethodAccessorImpl.invoke(NativeMethodAccessorImpl.java:77)
at java.base/jdk.internal.reflect.DelegatingMethodAccessorImpl.invoke(DelegatingMethodAccessorImpl.java:43)
at java.base/java.lang.reflect.Method.invoke(Method.java:568)
at org.testng.internal.invokers.MethodInvocationHelper.invokeMethod(MethodInvocationHelper.java:139)
at org.testng.internal.invokers.TestInvoker.invokeMethod(TestInvoker.java:677)
at org.testng.internal.invokers.TestInvoker.invokeTestMethod(TestInvoker.java:221)
at org.testng.internal.invokers.MethodRunner.runInSequence(MethodRunner.java:50)
at org.testng.internal.invokers.TestInvoker$MethodInvocationAgent.invoke(TestInvoker.java:962)
at org.testng.internal.invokers.TestInvoker.invokeTestMethods(TestInvoker.java:194)
at org.testng.internal.invokers.TestMethodWorker.invokeTestMethods(TestMethodWorker.java:148)
at org.testng.internal.invokers.TestMethodWorker.run(TestMethodWorker.java:128)
at java.base/java.util.ArrayList.forEach(ArrayList.java:1511)
at org.testng.TestRunner.privateRun(TestRunner.java:806)
at org.testng.TestRunner.run(TestRunner.java:601)
at org.testng.SuiteRunner.runTest(SuiteRunner.java:433)
at org.testng.SuiteRunner.runSequentially(SuiteRunner.java:427)
at org.testng.SuiteRunner.privateRun(SuiteRunner.java:387)
at org.testng.SuiteRunner.run(SuiteRunner.java:330)
at org.testng.SuiteRunnerWorker.runSuite(SuiteRunnerWorker.java:52)
at org.testng.SuiteRunnerWorker.run(SuiteRunnerWorker.java:95)
at org.testng.TestNG.runSuitesSequentially(TestNG.java:1256)
at org.testng.TestNG.runSuitesLocally(TestNG.java:1176)
at org.testng.TestNG.runSuites(TestNG.java:1099)
at org.testng.TestNG.run(TestNG.java:1067)
at org.testng.remote.AbstractRemoteTestNG.run(AbstractRemoteTestNG.java:115)
at org.testng.remote.RemoteTestNG.initAndRun(RemoteTestNG.java:251)
at org.testng.remote.RemoteTestNG.main(RemoteTestNG.java:77)
]]>
            </full-stacktrace>
          </exception> <!-- java.lang.AssertionError -->
          <reporter-output>
          </reporter-output>
        </test-method> <!-- checkcontentEncoding -->
        <test-method signature="checkserverType()[pri:0, instance:com.employeeapi.testCases.TC004_Put_Employee_Record@3a93b025]" started-at="2022-09-10T00:49:55 IST" name="checkserverType" finished-at="2022-09-10T00:49:55 IST" duration-ms="4" status="FAIL">
          <exception class="java.lang.AssertionError">
            <message>
              <![CDATA[expected [nginx/1.14.1] but found [nginx]]]>
            </message>
            <full-stacktrace>
              <![CDATA[java.lang.AssertionError: expected [nginx/1.14.1] but found [nginx]
at org.testng.Assert.fail(Assert.java:110)
at org.testng.Assert.failNotEquals(Assert.java:1413)
at org.testng.Assert.assertEqualsImpl(Assert.java:149)
at org.testng.Assert.assertEquals(Assert.java:131)
at org.testng.Assert.assertEquals(Assert.java:655)
at org.testng.Assert.assertEquals(Assert.java:665)
at com.employeeapi.testCases.TC004_Put_Employee_Record.checkserverType(TC004_Put_Employee_Record.java:95)
at java.base/jdk.internal.reflect.NativeMethodAccessorImpl.invoke0(Native Method)
at java.base/jdk.internal.reflect.NativeMethodAccessorImpl.invoke(NativeMethodAccessorImpl.java:77)
at java.base/jdk.internal.reflect.DelegatingMethodAccessorImpl.invoke(DelegatingMethodAccessorImpl.java:43)
at java.base/java.lang.reflect.Method.invoke(Method.java:568)
at org.testng.internal.invokers.MethodInvocationHelper.invokeMethod(MethodInvocationHelper.java:139)
at org.testng.internal.invokers.TestInvoker.invokeMethod(TestInvoker.java:677)
at org.testng.internal.invokers.TestInvoker.invokeTestMethod(TestInvoker.java:221)
at org.testng.internal.invokers.MethodRunner.runInSequence(MethodRunner.java:50)
at org.testng.internal.invokers.TestInvoker$MethodInvocationAgent.invoke(TestInvoker.java:962)
at org.testng.internal.invokers.TestInvoker.invokeTestMethods(TestInvoker.java:194)
at org.testng.internal.invokers.TestMethodWorker.invokeTestMethods(TestMethodWorker.java:148)
at org.testng.internal.invokers.TestMethodWorker.run(TestMethodWorker.java:128)
at java.base/java.util.ArrayList.forEach(ArrayList.java:1511)
at org.testng.TestRunner.privateRun(TestRunner.java:806)
at org.testng.TestRunner.run(TestRunner.java:601)
at org.testng.SuiteRunner.runTest(SuiteRunner.java:433)
at org.testng.SuiteRunner.runSequentially(SuiteRunner.java:427)
at org.testng.SuiteRunner.privateRun(SuiteRunner.java:387)
at org.testng.SuiteRunner.run(SuiteRunner.java:330)
at org.testng.SuiteRunnerWorker.runSuite(SuiteRunnerWorker.java:52)
at org.testng.SuiteRunnerWorker.run(SuiteRunnerWorker.java:95)
at org.testng.TestNG.runSuitesSequentially(TestNG.java:1256)
at org.testng.TestNG.runSuitesLocally(TestNG.java:1176)
at org.testng.TestNG.runSuites(TestNG.java:1099)
at org.testng.TestNG.run(TestNG.java:1067)
at org.testng.remote.AbstractRemoteTestNG.run(AbstractRemoteTestNG.java:115)
at org.testng.remote.RemoteTestNG.initAndRun(RemoteTestNG.java:251)
at org.testng.remote.RemoteTestNG.main(RemoteTestNG.java:77)
]]>
            </full-stacktrace>
          </exception> <!-- java.lang.AssertionError -->
          <reporter-output>
          </reporter-output>
        </test-method> <!-- checkserverType -->
        <test-method signature="checkstatusLine()[pri:0, instance:com.employeeapi.testCases.TC004_Put_Employee_Record@3a93b025]" started-at="2022-09-10T00:49:55 IST" name="checkstatusLine" finished-at="2022-09-10T00:49:55 IST" duration-ms="3" status="PASS">
          <reporter-output>
          </reporter-output>
        </test-method> <!-- checkstatusLine -->
        <test-method is-config="true" signature="tearDown()[pri:0, instance:com.employeeapi.testCases.TC004_Put_Employee_Record@3a93b025]" started-at="2022-09-10T00:49:55 IST" name="tearDown" finished-at="2022-09-10T00:49:55 IST" duration-ms="3" status="PASS">
          <reporter-output>
          </reporter-output>
        </test-method> <!-- tearDown -->
      </class> <!-- com.employeeapi.testCases.TC004_Put_Employee_Record -->
      <class name="com.employeeapi.testCases.TC002_Get_Single_Employee_Record">
        <test-method is-config="true" signature="setup()[pri:0, instance:com.employeeapi.testCases.TC002_Get_Single_Employee_Record@222545dc]" started-at="2022-09-10T00:49:34 IST" name="setup" finished-at="2022-09-10T00:49:34 IST" duration-ms="3" status="PASS">
          <reporter-output>
          </reporter-output>
        </test-method> <!-- setup -->
        <test-method is-config="true" signature="getEmployeeData()[pri:0, instance:com.employeeapi.testCases.TC002_Get_Single_Employee_Record@222545dc]" started-at="2022-09-10T00:49:34 IST" name="getEmployeeData" finished-at="2022-09-10T00:49:42 IST" duration-ms="7761" status="PASS">
          <reporter-output>
          </reporter-output>
        </test-method> <!-- getEmployeeData -->
        <test-method signature="checkContentLenght()[pri:0, instance:com.employeeapi.testCases.TC002_Get_Single_Employee_Record@222545dc]" started-at="2022-09-10T00:49:42 IST" name="checkContentLenght" finished-at="2022-09-10T00:49:42 IST" duration-ms="3" status="FAIL">
          <exception class="java.lang.NumberFormatException">
            <message>
              <![CDATA[Cannot parse null string]]>
            </message>
            <full-stacktrace>
              <![CDATA[java.lang.NumberFormatException: Cannot parse null string
at java.base/java.lang.Integer.parseInt(Integer.java:630)
at java.base/java.lang.Integer.parseInt(Integer.java:786)
at com.employeeapi.testCases.TC002_Get_Single_Employee_Record.checkContentLenght(TC002_Get_Single_Employee_Record.java:84)
at java.base/jdk.internal.reflect.NativeMethodAccessorImpl.invoke0(Native Method)
at java.base/jdk.internal.reflect.NativeMethodAccessorImpl.invoke(NativeMethodAccessorImpl.java:77)
at java.base/jdk.internal.reflect.DelegatingMethodAccessorImpl.invoke(DelegatingMethodAccessorImpl.java:43)
at java.base/java.lang.reflect.Method.invoke(Method.java:568)
at org.testng.internal.invokers.MethodInvocationHelper.invokeMethod(MethodInvocationHelper.java:139)
at org.testng.internal.invokers.TestInvoker.invokeMethod(TestInvoker.java:677)
at org.testng.internal.invokers.TestInvoker.invokeTestMethod(TestInvoker.java:221)
at org.testng.internal.invokers.MethodRunner.runInSequence(MethodRunner.java:50)
at org.testng.internal.invokers.TestInvoker$MethodInvocationAgent.invoke(TestInvoker.java:962)
at org.testng.internal.invokers.TestInvoker.invokeTestMethods(TestInvoker.java:194)
at org.testng.internal.invokers.TestMethodWorker.invokeTestMethods(TestMethodWorker.java:148)
at org.testng.internal.invokers.TestMethodWorker.run(TestMethodWorker.java:128)
at java.base/java.util.ArrayList.forEach(ArrayList.java:1511)
at org.testng.TestRunner.privateRun(TestRunner.java:806)
at org.testng.TestRunner.run(TestRunner.java:601)
at org.testng.SuiteRunner.runTest(SuiteRunner.java:433)
at org.testng.SuiteRunner.runSequentially(SuiteRunner.java:427)
at org.testng.SuiteRunner.privateRun(SuiteRunner.java:387)
at org.testng.SuiteRunner.run(SuiteRunner.java:330)
at org.testng.SuiteRunnerWorker.runSuite(SuiteRunnerWorker.java:52)
at org.testng.SuiteRunnerWorker.run(SuiteRunnerWorker.java:95)
at org.testng.TestNG.runSuitesSequentially(TestNG.java:1256)
at org.testng.TestNG.runSuitesLocally(TestNG.java:1176)
at org.testng.TestNG.runSuites(TestNG.java:1099)
at org.testng.TestNG.run(TestNG.java:1067)
at org.testng.remote.AbstractRemoteTestNG.run(AbstractRemoteTestNG.java:115)
at org.testng.remote.RemoteTestNG.initAndRun(RemoteTestNG.java:251)
at org.testng.remote.RemoteTestNG.main(RemoteTestNG.java:77)
]]>
            </full-stacktrace>
          </exception> <!-- java.lang.NumberFormatException -->
          <reporter-output>
          </reporter-output>
        </test-method> <!-- checkContentLenght -->
        <test-method signature="checkContentType()[pri:0, instance:com.employeeapi.testCases.TC002_Get_Single_Employee_Record@222545dc]" started-at="2022-09-10T00:49:42 IST" name="checkContentType" finished-at="2022-09-10T00:49:42 IST" duration-ms="11" status="PASS">
          <reporter-output>
          </reporter-output>
        </test-method> <!-- checkContentType -->
        <test-method signature="checkResponseTime()[pri:0, instance:com.employeeapi.testCases.TC002_Get_Single_Employee_Record@222545dc]" started-at="2022-09-10T00:49:42 IST" name="checkResponseTime" finished-at="2022-09-10T00:49:42 IST" duration-ms="2" status="PASS">
          <reporter-output>
          </reporter-output>
        </test-method> <!-- checkResponseTime -->
        <test-method signature="checkResposeBody()[pri:0, instance:com.employeeapi.testCases.TC002_Get_Single_Employee_Record@222545dc]" started-at="2022-09-10T00:49:42 IST" name="checkResposeBody" finished-at="2022-09-10T00:49:42 IST" duration-ms="11" status="FAIL">
          <exception class="java.lang.AssertionError">
            <message>
              <![CDATA[expected [true] but found [false]]]>
            </message>
            <full-stacktrace>
              <![CDATA[java.lang.AssertionError: expected [true] but found [false]
at org.testng.Assert.fail(Assert.java:110)
at org.testng.Assert.failNotEquals(Assert.java:1413)
at org.testng.Assert.assertEqualsImpl(Assert.java:149)
at org.testng.Assert.assertEquals(Assert.java:131)
at org.testng.Assert.assertEquals(Assert.java:976)
at org.testng.Assert.assertEquals(Assert.java:1010)
at com.employeeapi.testCases.TC002_Get_Single_Employee_Record.checkResposeBody(TC002_Get_Single_Employee_Record.java:46)
at java.base/jdk.internal.reflect.NativeMethodAccessorImpl.invoke0(Native Method)
at java.base/jdk.internal.reflect.NativeMethodAccessorImpl.invoke(NativeMethodAccessorImpl.java:77)
at java.base/jdk.internal.reflect.DelegatingMethodAccessorImpl.invoke(DelegatingMethodAccessorImpl.java:43)
at java.base/java.lang.reflect.Method.invoke(Method.java:568)
at org.testng.internal.invokers.MethodInvocationHelper.invokeMethod(MethodInvocationHelper.java:139)
at org.testng.internal.invokers.TestInvoker.invokeMethod(TestInvoker.java:677)
at org.testng.internal.invokers.TestInvoker.invokeTestMethod(TestInvoker.java:221)
at org.testng.internal.invokers.MethodRunner.runInSequence(MethodRunner.java:50)
at org.testng.internal.invokers.TestInvoker$MethodInvocationAgent.invoke(TestInvoker.java:962)
at org.testng.internal.invokers.TestInvoker.invokeTestMethods(TestInvoker.java:194)
at org.testng.internal.invokers.TestMethodWorker.invokeTestMethods(TestMethodWorker.java:148)
at org.testng.internal.invokers.TestMethodWorker.run(TestMethodWorker.java:128)
at java.base/java.util.ArrayList.forEach(ArrayList.java:1511)
at org.testng.TestRunner.privateRun(TestRunner.java:806)
at org.testng.TestRunner.run(TestRunner.java:601)
at org.testng.SuiteRunner.runTest(SuiteRunner.java:433)
at org.testng.SuiteRunner.runSequentially(SuiteRunner.java:427)
at org.testng.SuiteRunner.privateRun(SuiteRunner.java:387)
at org.testng.SuiteRunner.run(SuiteRunner.java:330)
at org.testng.SuiteRunnerWorker.runSuite(SuiteRunnerWorker.java:52)
at org.testng.SuiteRunnerWorker.run(SuiteRunnerWorker.java:95)
at org.testng.TestNG.runSuitesSequentially(TestNG.java:1256)
at org.testng.TestNG.runSuitesLocally(TestNG.java:1176)
at org.testng.TestNG.runSuites(TestNG.java:1099)
at org.testng.TestNG.run(TestNG.java:1067)
at org.testng.remote.AbstractRemoteTestNG.run(AbstractRemoteTestNG.java:115)
at org.testng.remote.RemoteTestNG.initAndRun(RemoteTestNG.java:251)
at org.testng.remote.RemoteTestNG.main(RemoteTestNG.java:77)
]]>
            </full-stacktrace>
          </exception> <!-- java.lang.AssertionError -->
          <reporter-output>
          </reporter-output>
        </test-method> <!-- checkResposeBody -->
        <test-method signature="checkStatusCode()[pri:0, instance:com.employeeapi.testCases.TC002_Get_Single_Employee_Record@222545dc]" started-at="2022-09-10T00:49:42 IST" name="checkStatusCode" finished-at="2022-09-10T00:49:42 IST" duration-ms="3" status="FAIL">
          <exception class="java.lang.AssertionError">
            <message>
              <![CDATA[expected [200] but found [429]]]>
            </message>
            <full-stacktrace>
              <![CDATA[java.lang.AssertionError: expected [200] but found [429]
at org.testng.Assert.fail(Assert.java:110)
at org.testng.Assert.failNotEquals(Assert.java:1413)
at org.testng.Assert.assertEqualsImpl(Assert.java:149)
at org.testng.Assert.assertEquals(Assert.java:131)
at org.testng.Assert.assertEquals(Assert.java:1240)
at org.testng.Assert.assertEquals(Assert.java:1274)
at com.employeeapi.testCases.TC002_Get_Single_Employee_Record.checkStatusCode(TC002_Get_Single_Employee_Record.java:52)
at java.base/jdk.internal.reflect.NativeMethodAccessorImpl.invoke0(Native Method)
at java.base/jdk.internal.reflect.NativeMethodAccessorImpl.invoke(NativeMethodAccessorImpl.java:77)
at java.base/jdk.internal.reflect.DelegatingMethodAccessorImpl.invoke(DelegatingMethodAccessorImpl.java:43)
at java.base/java.lang.reflect.Method.invoke(Method.java:568)
at org.testng.internal.invokers.MethodInvocationHelper.invokeMethod(MethodInvocationHelper.java:139)
at org.testng.internal.invokers.TestInvoker.invokeMethod(TestInvoker.java:677)
at org.testng.internal.invokers.TestInvoker.invokeTestMethod(TestInvoker.java:221)
at org.testng.internal.invokers.MethodRunner.runInSequence(MethodRunner.java:50)
at org.testng.internal.invokers.TestInvoker$MethodInvocationAgent.invoke(TestInvoker.java:962)
at org.testng.internal.invokers.TestInvoker.invokeTestMethods(TestInvoker.java:194)
at org.testng.internal.invokers.TestMethodWorker.invokeTestMethods(TestMethodWorker.java:148)
at org.testng.internal.invokers.TestMethodWorker.run(TestMethodWorker.java:128)
at java.base/java.util.ArrayList.forEach(ArrayList.java:1511)
at org.testng.TestRunner.privateRun(TestRunner.java:806)
at org.testng.TestRunner.run(TestRunner.java:601)
at org.testng.SuiteRunner.runTest(SuiteRunner.java:433)
at org.testng.SuiteRunner.runSequentially(SuiteRunner.java:427)
at org.testng.SuiteRunner.privateRun(SuiteRunner.java:387)
at org.testng.SuiteRunner.run(SuiteRunner.java:330)
at org.testng.SuiteRunnerWorker.runSuite(SuiteRunnerWorker.java:52)
at org.testng.SuiteRunnerWorker.run(SuiteRunnerWorker.java:95)
at org.testng.TestNG.runSuitesSequentially(TestNG.java:1256)
at org.testng.TestNG.runSuitesLocally(TestNG.java:1176)
at org.testng.TestNG.runSuites(TestNG.java:1099)
at org.testng.TestNG.run(TestNG.java:1067)
at org.testng.remote.AbstractRemoteTestNG.run(AbstractRemoteTestNG.java:115)
at org.testng.remote.RemoteTestNG.initAndRun(RemoteTestNG.java:251)
at org.testng.remote.RemoteTestNG.main(RemoteTestNG.java:77)
]]>
            </full-stacktrace>
          </exception> <!-- java.lang.AssertionError -->
          <reporter-output>
          </reporter-output>
        </test-method> <!-- checkStatusCode -->
        <test-method signature="checkserverType()[pri:0, instance:com.employeeapi.testCases.TC002_Get_Single_Employee_Record@222545dc]" started-at="2022-09-10T00:49:42 IST" name="checkserverType" finished-at="2022-09-10T00:49:42 IST" duration-ms="2" status="FAIL">
          <exception class="java.lang.AssertionError">
            <message>
              <![CDATA[expected [nginx/1.14.1] but found [nginx]]]>
            </message>
            <full-stacktrace>
              <![CDATA[java.lang.AssertionError: expected [nginx/1.14.1] but found [nginx]
at org.testng.Assert.fail(Assert.java:110)
at org.testng.Assert.failNotEquals(Assert.java:1413)
at org.testng.Assert.assertEqualsImpl(Assert.java:149)
at org.testng.Assert.assertEquals(Assert.java:131)
at org.testng.Assert.assertEquals(Assert.java:655)
at org.testng.Assert.assertEquals(Assert.java:665)
at com.employeeapi.testCases.TC002_Get_Single_Employee_Record.checkserverType(TC002_Get_Single_Employee_Record.java:78)
at java.base/jdk.internal.reflect.NativeMethodAccessorImpl.invoke0(Native Method)
at java.base/jdk.internal.reflect.NativeMethodAccessorImpl.invoke(NativeMethodAccessorImpl.java:77)
at java.base/jdk.internal.reflect.DelegatingMethodAccessorImpl.invoke(DelegatingMethodAccessorImpl.java:43)
at java.base/java.lang.reflect.Method.invoke(Method.java:568)
at org.testng.internal.invokers.MethodInvocationHelper.invokeMethod(MethodInvocationHelper.java:139)
at org.testng.internal.invokers.TestInvoker.invokeMethod(TestInvoker.java:677)
at org.testng.internal.invokers.TestInvoker.invokeTestMethod(TestInvoker.java:221)
at org.testng.internal.invokers.MethodRunner.runInSequence(MethodRunner.java:50)
at org.testng.internal.invokers.TestInvoker$MethodInvocationAgent.invoke(TestInvoker.java:962)
at org.testng.internal.invokers.TestInvoker.invokeTestMethods(TestInvoker.java:194)
at org.testng.internal.invokers.TestMethodWorker.invokeTestMethods(TestMethodWorker.java:148)
at org.testng.internal.invokers.TestMethodWorker.run(TestMethodWorker.java:128)
at java.base/java.util.ArrayList.forEach(ArrayList.java:1511)
at org.testng.TestRunner.privateRun(TestRunner.java:806)
at org.testng.TestRunner.run(TestRunner.java:601)
at org.testng.SuiteRunner.runTest(SuiteRunner.java:433)
at org.testng.SuiteRunner.runSequentially(SuiteRunner.java:427)
at org.testng.SuiteRunner.privateRun(SuiteRunner.java:387)
at org.testng.SuiteRunner.run(SuiteRunner.java:330)
at org.testng.SuiteRunnerWorker.runSuite(SuiteRunnerWorker.java:52)
at org.testng.SuiteRunnerWorker.run(SuiteRunnerWorker.java:95)
at org.testng.TestNG.runSuitesSequentially(TestNG.java:1256)
at org.testng.TestNG.runSuitesLocally(TestNG.java:1176)
at org.testng.TestNG.runSuites(TestNG.java:1099)
at org.testng.TestNG.run(TestNG.java:1067)
at org.testng.remote.AbstractRemoteTestNG.run(AbstractRemoteTestNG.java:115)
at org.testng.remote.RemoteTestNG.initAndRun(RemoteTestNG.java:251)
at org.testng.remote.RemoteTestNG.main(RemoteTestNG.java:77)
]]>
            </full-stacktrace>
          </exception> <!-- java.lang.AssertionError -->
          <reporter-output>
          </reporter-output>
        </test-method> <!-- checkserverType -->
        <test-method signature="checkstatusLine()[pri:0, instance:com.employeeapi.testCases.TC002_Get_Single_Employee_Record@222545dc]" started-at="2022-09-10T00:49:42 IST" name="checkstatusLine" finished-at="2022-09-10T00:49:42 IST" duration-ms="2" status="FAIL">
          <exception class="java.lang.AssertionError">
            <message>
              <![CDATA[expected [HTTP/1.1 200 OK] but found [HTTP/1.1 429 Too Many Requests]]]>
            </message>
            <full-stacktrace>
              <![CDATA[java.lang.AssertionError: expected [HTTP/1.1 200 OK] but found [HTTP/1.1 429 Too Many Requests]
at org.testng.Assert.fail(Assert.java:110)
at org.testng.Assert.failNotEquals(Assert.java:1413)
at org.testng.Assert.assertEqualsImpl(Assert.java:149)
at org.testng.Assert.assertEquals(Assert.java:131)
at org.testng.Assert.assertEquals(Assert.java:655)
at org.testng.Assert.assertEquals(Assert.java:665)
at com.employeeapi.testCases.TC002_Get_Single_Employee_Record.checkstatusLine(TC002_Get_Single_Employee_Record.java:65)
at java.base/jdk.internal.reflect.NativeMethodAccessorImpl.invoke0(Native Method)
at java.base/jdk.internal.reflect.NativeMethodAccessorImpl.invoke(NativeMethodAccessorImpl.java:77)
at java.base/jdk.internal.reflect.DelegatingMethodAccessorImpl.invoke(DelegatingMethodAccessorImpl.java:43)
at java.base/java.lang.reflect.Method.invoke(Method.java:568)
at org.testng.internal.invokers.MethodInvocationHelper.invokeMethod(MethodInvocationHelper.java:139)
at org.testng.internal.invokers.TestInvoker.invokeMethod(TestInvoker.java:677)
at org.testng.internal.invokers.TestInvoker.invokeTestMethod(TestInvoker.java:221)
at org.testng.internal.invokers.MethodRunner.runInSequence(MethodRunner.java:50)
at org.testng.internal.invokers.TestInvoker$MethodInvocationAgent.invoke(TestInvoker.java:962)
at org.testng.internal.invokers.TestInvoker.invokeTestMethods(TestInvoker.java:194)
at org.testng.internal.invokers.TestMethodWorker.invokeTestMethods(TestMethodWorker.java:148)
at org.testng.internal.invokers.TestMethodWorker.run(TestMethodWorker.java:128)
at java.base/java.util.ArrayList.forEach(ArrayList.java:1511)
at org.testng.TestRunner.privateRun(TestRunner.java:806)
at org.testng.TestRunner.run(TestRunner.java:601)
at org.testng.SuiteRunner.runTest(SuiteRunner.java:433)
at org.testng.SuiteRunner.runSequentially(SuiteRunner.java:427)
at org.testng.SuiteRunner.privateRun(SuiteRunner.java:387)
at org.testng.SuiteRunner.run(SuiteRunner.java:330)
at org.testng.SuiteRunnerWorker.runSuite(SuiteRunnerWorker.java:52)
at org.testng.SuiteRunnerWorker.run(SuiteRunnerWorker.java:95)
at org.testng.TestNG.runSuitesSequentially(TestNG.java:1256)
at org.testng.TestNG.runSuitesLocally(TestNG.java:1176)
at org.testng.TestNG.runSuites(TestNG.java:1099)
at org.testng.TestNG.run(TestNG.java:1067)
at org.testng.remote.AbstractRemoteTestNG.run(AbstractRemoteTestNG.java:115)
at org.testng.remote.RemoteTestNG.initAndRun(RemoteTestNG.java:251)
at org.testng.remote.RemoteTestNG.main(RemoteTestNG.java:77)
]]>
            </full-stacktrace>
          </exception> <!-- java.lang.AssertionError -->
          <reporter-output>
          </reporter-output>
        </test-method> <!-- checkstatusLine -->
        <test-method is-config="true" signature="tearDown()[pri:0, instance:com.employeeapi.testCases.TC002_Get_Single_Employee_Record@222545dc]" started-at="2022-09-10T00:49:42 IST" name="tearDown" finished-at="2022-09-10T00:49:42 IST" duration-ms="1" status="PASS">
          <reporter-output>
          </reporter-output>
        </test-method> <!-- tearDown -->
      </class> <!-- com.employeeapi.testCases.TC002_Get_Single_Employee_Record -->
    </test> <!-- EmployeesRestAPITest -->
  </suite> <!-- EmployeesRestAPISuite -->
</testng-results>
